Workbook
Name TotalSupply: 'Supply (Allocation & Emissions)'!$I$1

Sheet Supply Charts

Sheet Supply (Allocation & Emissions)
G1: Total Number of Tokens | I1: 800000000
G2: Total % of Tokens Allocated | I2: =SUM(I6:AG6) -> 1
G3: All Tokens Emitted Check | I3: =MAX(H18:H1004)=I1 -> TRUE
H5: Role | I5: Team | J5: Foundation | K5: Advisors | L5: Private Investors | M5: Public rounds | N5: Community Rewards | O5: Ecosystem growth fund | P5: Staking | Q5: Air drops | R5: Treasury | S5: Testnet Incentive
H6: % Allocation | I6: 0.13 | J6: 0.115 | K6: 0.04 | L6: 0.015 | M6: 0.005 | N6: 0.07 | O6: 0.06 | P6: 0.5 | Q6: 0.025 | R6: 0.036 | S6: 0.004
H7: Vesting Months | I7: 48 | J7: 48 | K7: 24 | L7: 36 | M7: 24 | N7: 2 | O7: 2 | P7: 6 | Q7: 0 | R7: 2 | S7: 2
H8: Cliff Months | I8: 12 | J8: 12 | K8: 6 | L8: 12 | M8: 6 | N8: 0 | O8: 0 | P8: 0 | Q8: 0 | R8: 0 | S8: 0
H9: Delay Months | I9: 0 | J9: 0 | K9: 0 | L9: 0 | M9: 0 | N9: 0 | O9: 0 | P9: 0 | Q9: 0 | R9: 0 | S9: 0
H10: Spacing Months | I10: 0 | J10: 0 | K10: 0 | L10: 0 | M10: 0 | N10: 0 | O10: 0 | P10: 0 | Q10: 0 | R10: 0 | S10: 0
H11: Curve Type | I11: Sigmoid | J11: Sigmoid | K11: Linear | L11: Sigmoid | M11: Sigmoid | N11: Linear | O11: Linear | P11: Linear | Q11: Linear | R11: Linear | S11: Linear
H12: Backweight Factor | I12: 20 | J12: 20 | K12: 12 | L12: 15 | M12: 15 | N12: 20 | O12: 20 | P12: 20 | Q12: 20 | R12: 20 | S12: 20 | T12: 20 | U12: 20 | V12: 20 | W12: 20 | X12: 20 | Y12: 20 | Z12: 20 | AA12: 20 | AB12: 20 | AC12: 20 | AD12: 20 | AE12: 20 | AF12: 20 | AG12: 20
H13: Slope Factor | I13: 8 | J13: 8 | K13: 0 | L13: 5 | M13: 5 | N13: 8 | O13: 8 | P13: 8 | Q13: 8 | R13: 8 | S13: 8 | T13: 8 | U13: 8 | V13: 8 | W13: 8 | X13: 8 | Y13: 8 | Z13: 8 | AA13: 8 | AB13: 8 | AC13: 8 | AD13: 8 | AE13: 8 | AF13: 8 | AG13: 8
G14: CHECKS | H14: Max Vest | I14: =I7+I9<=120 -> TRUE | J14: =J7+J9<=120 -> TRUE | K14: =K7+K9<=120 -> TRUE | L14: =L7+L9<=120 -> TRUE | M14: =M7+M9<=120 -> TRUE | N14: =N7+N9<=120 -> TRUE | O14: =O7+O9<=120 -> TRUE | P14: =P7+P9<=120 -> TRUE | ... AG14: =AG7+AG9<=120 -> TRUE
H15: Valid Spacing | I15: =IF(I10=0,TRUE,MOD(I7,I10)=0) -> TRUE | J15: =IF(J10=0,TRUE,MOD(J7,J10)=0) -> TRUE | K15: =IF(K10=0,TRUE,MOD(K7,K10)=0) -> TRUE | L15: =IF(L10=0,TRUE,MOD(L7,L10)=0) -> TRUE | M15: =IF(M10=0,TRUE,MOD(M7,M10)=0) -> TRUE | N15: =IF(N10=0,TRUE,MOD(N7,N10)=0) -> TRUE | O15: =IF(O10=0,TRUE,MOD(O7,O10)=0) -> TRUE | P15: =IF(P10=0,TRUE,MOD(P7,P10)=0) -> TRUE | ... AG15: =IF(AG10=0,TRUE,MOD(AG7,AG10)=0) -> TRUE
H16: Emitted Check | I16: =MAX(I18:I1004)=I6*TotalSupply -> TRUE | J16: =MAX(J18:J1004)=J6*TotalSupply -> TRUE | K16: =MAX(K18:K1004)=K6*TotalSupply -> TRUE | L16: =MAX(L18:L1004)=L6*TotalSupply -> TRUE | M16: =MAX(M18:M1004)=M6*TotalSupply -> TRUE | N16: =MAX(N17:N1004)=N6*TotalSupply -> TRUE | O16: =MAX(O17:O1004)=O6*TotalSupply -> TRUE | P16: =MAX(P17:P1004)=P6*TotalSupply -> TRUE | Q16: =MAX(Q18:Q1004)=Q6*TotalSupply -> TRUE | R16: =MAX(R18:R1004)=R6*TotalSupply -> TRUE | S16: =MAX(S18:S1004)=S6*TotalSupply -> TRUE | T16: =MAX(T18:T1004)=T6*TotalSupply -> TRUE | U16: =MAX(U18:U1004)=U6*TotalSupply -> TRUE | V16: =MAX(V18:V1004)=V6*TotalSupply -> TRUE | W16: =MAX(W18:W1004)=W6*TotalSupply -> TRUE | X16: =MAX(X18:X1004)=X6*TotalSupply -> TRUE | ... AG16: =MAX(AG18:AG1004)=AG6*TotalSupply -> TRUE
A18: At End of Month... | B18: Linear Comparison | C18: Linear MoM | D18: Emissions MoM | E18: Linear Annualized Inflation Rate | F18: Annualized Inflation Rate | G18: % of Total | H18: Total | I18: =I5 -> Team | J18: =J5 -> Foundation | K18: =K5 -> Advisors | L18: =L5 -> Private Investors | M18: =M5 -> Public rounds | N18: =N5 -> Community Rewards | O18: =O5 -> Ecosystem growth fund | P18: =P5 -> Staking | ... S18: =S5 -> Testnet Incentive
A19: 0 | B19: =G19 -> 0.025 | G19: =H19/TotalSupply -> 0.025 | H19: =SUM(I19:AG19) -> 20000000 | I19: =TotalSupply*I$6*MAX(0,MIN(1,IF(I$11="Linear",('Linear Curves'!B13-'Linear Curves'!B$8)/('Linear Curves'!B$10),('Sigmoid Curves'!B13-'Sigmoid Curves'!B$8)/('Sigmoid Curves'!B$10)))) -> 0 | J19: =TotalSupply*J$6*MAX(0,MIN(1,IF(J$11="Linear",('Linear Curves'!C13-'Linear Curves'!C$8)/('Linear Curves'!C$10),('Sigmoid Curves'!C13-'Sigmoid Curves'!C$8)/('Sigmoid Curves'!C$10)))) -> 0 | K19: =TotalSupply*K$6*MAX(0,MIN(1,IF(K$11="Linear",('Linear Curves'!D13-'Linear Curves'!D$8)/('Linear Curves'!D$10),('Sigmoid Curves'!D13-'Sigmoid Curves'!D$8)/('Sigmoid Curves'!D$10)))) -> 0 | L19: =TotalSupply*L$6*MAX(0,MIN(1,IF(L$11="Linear",('Linear Curves'!F13-'Linear Curves'!F$8)/('Linear Curves'!F$10),('Sigmoid Curves'!F13-'Sigmoid Curves'!F$8)/('Sigmoid Curves'!F$10)))) -> 0 | M19: =TotalSupply*M$6*MAX(0,MIN(1,IF(M$11="Linear",('Linear Curves'!G13-'Linear Curves'!G$8)/('Linear Curves'!G$10),('Sigmoid Curves'!G13-'Sigmoid Curves'!G$8)/('Sigmoid Curves'!G$10)))) -> 0 | N19: =TotalSupply*N$6*MAX(0,MIN(1,IF(N$11="Linear",('Linear Curves'!H13-'Linear Curves'!H$8)/('Linear Curves'!H$10),('Sigmoid Curves'!H13-'Sigmoid Curves'!H$8)/('Sigmoid Curves'!H$10)))) -> 0 | O19: =TotalSupply*O$6*MAX(0,MIN(1,IF(O$11="Linear",('Linear Curves'!I13-'Linear Curves'!I$8)/('Linear Curves'!I$10),('Sigmoid Curves'!I13-'Sigmoid Curves'!I$8)/('Sigmoid Curves'!I$10)))) -> 0 | P19: =TotalSupply*P$6*MAX(0,MIN(1,IF(P$11="Linear",('Linear Curves'!I13-'Linear Curves'!I$8)/('Linear Curves'!I$10),('Sigmoid Curves'!I13-'Sigmoid Curves'!I$8)/('Sigmoid Curves'!I$10)))) -> 0 | Q19: =TotalSupply*Q$6*MAX(0,MIN(1,IF(Q$11="Linear",('Linear Curves'!J13-'Linear Curves'!J$8)/('Linear Curves'!J$10),('Sigmoid Curves'!J13-'Sigmoid Curves'!J$8)/('Sigmoid Curves'!J$10)))) -> 20000000 | R19: =TotalSupply*R$6*MAX(0,MIN(1,IF(R$11="Linear",('Linear Curves'!K13-'Linear Curves'!K$8)/('Linear Curves'!K$10),('Sigmoid Curves'!K13-'Sigmoid Curves'!K$8)/('Sigmoid Curves'!K$10)))) -> 0 | S19: =TotalSupply*S$6*MAX(0,MIN(1,IF(S$11="Linear",('Linear Curves'!L13-'Linear Curves'!L$8)/('Linear Curves'!L$10),('Sigmoid Curves'!L13-'Sigmoid Curves'!L$8)/('Sigmoid Curves'!L$10)))) -> 0
A20: 1 | B20: =MIN(1,((1-G$19)/(MATCH(100%,G$19:G1004,0)-1)*A20)+G$19) -> 0.0453125 | C20: =B20-B19 -> 0.0203125 | D20: =G20-G19 -> 0.14833333 | E20: =((B20/B19)-1)*12 -> 9.75 | F20: =((H20/H19)-1)*12 -> 71.2 | G20: =H20/TotalSupply -> 0.17333333 | H20: =SUM(I20:AG20) -> 1.3866667e+08 | I20: =TotalSupply*I$6*MAX(0,MIN(1,IF(I$11="Linear",('Linear Curves'!B14-'Linear Curves'!B$8)/('Linear Curves'!B$10),('Sigmoid Curves'!B14-'Sigmoid Curves'!B$8)/('Sigmoid Curves'!B$10)))) -> 0 | J20: =TotalSupply*J$6*MAX(0,MIN(1,IF(J$11="Linear",('Linear Curves'!C14-'Linear Curves'!C$8)/('Linear Curves'!C$10),('Sigmoid Curves'!C14-'Sigmoid Curves'!C$8)/('Sigmoid Curves'!C$10)))) -> 0 | K20: =TotalSupply*K$6*MAX(0,MIN(1,IF(K$11="Linear",('Linear Curves'!D14-'Linear Curves'!D$8)/('Linear Curves'!D$10),('Sigmoid Curves'!D14-'Sigmoid Curves'!D$8)/('Sigmoid Curves'!D$10)))) -> 0 | L20: =TotalSupply*L$6*MAX(0,MIN(1,IF(L$11="Linear",('Linear Curves'!F14-'Linear Curves'!F$8)/('Linear Curves'!F$10),('Sigmoid Curves'!F14-'Sigmoid Curves'!F$8)/('Sigmoid Curves'!F$10)))) -> 0 | M20: =TotalSupply*M$6*MAX(0,MIN(1,IF(M$11="Linear",('Linear Curves'!G14-'Linear Curves'!G$8)/('Linear Curves'!G$10),('Sigmoid Curves'!G14-'Sigmoid Curves'!G$8)/('Sigmoid Curves'!G$10)))) -> 0 | N20: =TotalSupply*N$6*MAX(0,MIN(1,IF(N$11="Linear",('Linear Curves'!H14-'Linear Curves'!H$8)/('Linear Curves'!H$10),('Sigmoid Curves'!H14-'Sigmoid Curves'!H$8)/('Sigmoid Curves'!H$10)))) -> 28000000 | O20: =TotalSupply*O$6*MAX(0,MIN(1,IF(O$11="Linear",('Linear Curves'!I14-'Linear Curves'!I$8)/('Linear Curves'!I$10),('Sigmoid Curves'!I14-'Sigmoid Curves'!I$8)/('Sigmoid Curves'!I$10)))) -> 8000000 | P20: =TotalSupply*P$6*MAX(0,MIN(1,IF(P$11="Linear",('Linear Curves'!I14-'Linear Curves'!I$8)/('Linear Curves'!I$10),('Sigmoid Curves'!I14-'Sigmoid Curves'!I$8)/('Sigmoid Curves'!I$10)))) -> 66666667 | Q20: =TotalSupply*Q$6*MAX(0,MIN(1,IF(Q$11="Linear",('Linear Curves'!J14-'Linear Curves'!J$8)/('Linear Curves'!J$10),('Sigmoid Curves'!J14-'Sigmoid Curves'!J$8)/('Sigmoid Curves'!J$10)))) -> 20000000 | R20: =TotalSupply*R$6*MAX(0,MIN(1,IF(R$11="Linear",('Linear Curves'!K14-'Linear Curves'!K$8)/('Linear Curves'!K$10),('Sigmoid Curves'!K14-'Sigmoid Curves'!K$8)/('Sigmoid Curves'!K$10)))) -> 14400000 | S20: =TotalSupply*S$6*MAX(0,MIN(1,IF(S$11="Linear",('Linear Curves'!L14-'Linear Curves'!L$8)/('Linear Curves'!L$10),('Sigmoid Curves'!L14-'Sigmoid Curves'!L$8)/('Sigmoid Curves'!L$10)))) -> 1600000
A21: 2 | B21: =MIN(1,((1-G$19)/(MATCH(100%,G$19:G1005,0)-1)*A21)+G$19) -> 0.065625 | C21: =B21-B20 -> 0.0203125 | D21: =G21-G20 -> 0.14833333 | E21: =((B21/B20)-1)*12 -> 5.3793103 | F21: =((H21/H20)-1)*12 -> 10.269231 | G21: =H21/TotalSupply -> 0.32166667 | H21: =SUM(I21:AG21) -> 2.5733333e+08 | I21: =TotalSupply*I$6*MAX(0,MIN(1,IF(I$11="Linear",('Linear Curves'!B15-'Linear Curves'!B$8)/('Linear Curves'!B$10),('Sigmoid Curves'!B15-'Sigmoid Curves'!B$8)/('Sigmoid Curves'!B$10)))) -> 0 | J21: =TotalSupply*J$6*MAX(0,MIN(1,IF(J$11="Linear",('Linear Curves'!C15-'Linear Curves'!C$8)/('Linear Curves'!C$10),('Sigmoid Curves'!C15-'Sigmoid Curves'!C$8)/('Sigmoid Curves'!C$10)))) -> 0 | K21: =TotalSupply*K$6*MAX(0,MIN(1,IF(K$11="Linear",('Linear Curves'!D15-'Linear Curves'!D$8)/('Linear Curves'!D$10),('Sigmoid Curves'!D15-'Sigmoid Curves'!D$8)/('Sigmoid Curves'!D$10)))) -> 0 | L21: =TotalSupply*L$6*MAX(0,MIN(1,IF(L$11="Linear",('Linear Curves'!F15-'Linear Curves'!F$8)/('Linear Curves'!F$10),('Sigmoid Curves'!F15-'Sigmoid Curves'!F$8)/('Sigmoid Curves'!F$10)))) -> 0 | M21: =TotalSupply*M$6*MAX(0,MIN(1,IF(M$11="Linear",('Linear Curves'!G15-'Linear Curves'!G$8)/('Linear Curves'!G$10),('Sigmoid Curves'!G15-'Sigmoid Curves'!G$8)/('Sigmoid Curves'!G$10)))) -> 0 | N21: =TotalSupply*N$6*MAX(0,MIN(1,IF(N$11="Linear",('Linear Curves'!H15-'Linear Curves'!H$8)/('Linear Curves'!H$10),('Sigmoid Curves'!H15-'Sigmoid Curves'!H$8)/('Sigmoid Curves'!H$10)))) -> 56000000 | O21: =TotalSupply*O$6*MAX(0,MIN(1,IF(O$11="Linear",('Linear Curves'!I15-'Linear Curves'!I$8)/('Linear Curves'!I$10),('Sigmoid Curves'!I15-'Sigmoid Curves'!I$8)/('Sigmoid Curves'!I$10)))) -> 16000000 | P21: =TotalSupply*P$6*MAX(0,MIN(1,IF(P$11="Linear",('Linear Curves'!I15-'Linear Curves'!I$8)/('Linear Curves'!I$10),('Sigmoid Curves'!I15-'Sigmoid Curves'!I$8)/('Sigmoid Curves'!I$10)))) -> 1.3333333e+08 | Q21: =TotalSupply*Q$6*MAX(0,MIN(1,IF(Q$11="Linear",('Linear Curves'!J15-'Linear Curves'!J$8)/('Linear Curves'!J$10),('Sigmoid Curves'!J15-'Sigmoid Curves'!J$8)/('Sigmoid Curves'!J$10)))) -> 20000000 | R21: =TotalSupply*R$6*MAX(0,MIN(1,IF(R$11="Linear",('Linear Curves'!K15-'Linear Curves'!K$8)/('Linear Curves'!K$10),('Sigmoid Curves'!K15-'Sigmoid Curves'!K$8)/('Sigmoid Curves'!K$10)))) -> 28800000 | S21: =TotalSupply*S$6*MAX(0,MIN(1,IF(S$11="Linear",('Linear Curves'!L15-'Linear Curves'!L$8)/('Linear Curves'!L$10),('Sigmoid Curves'!L15-'Sigmoid Curves'!L$8)/('Sigmoid Curves'!L$10)))) -> 3200000
A22: 3 | B22: =MIN(1,((1-G$19)/(MATCH(100%,G$19:G1006,0)-1)*A22)+G$19) -> 0.0859375 | C22: =B22-B21 -> 0.0203125 | D22: =G22-G21 -> 0.093333333 | E22: =((B22/B21)-1)*12 -> 3.7142857 | F22: =((H22/H21)-1)*12 -> 3.4818653 | G22: =H22/TotalSupply -> 0.415 | H22: =SUM(I22:AG22) -> 332000000 | I22: =TotalSupply*I$6*MAX(0,MIN(1,IF(I$11="Linear",('Linear Curves'!B16-'Linear Curves'!B$8)/('Linear Curves'!B$10),('Sigmoid Curves'!B16-'Sigmoid Curves'!B$8)/('Sigmoid Curves'!B$10)))) -> 0 | J22: =TotalSupply*J$6*MAX(0,MIN(1,IF(J$11="Linear",('Linear Curves'!C16-'Linear Curves'!C$8)/('Linear Curves'!C$10),('Sigmoid Curves'!C16-'Sigmoid Curves'!C$8)/('Sigmoid Curves'!C$10)))) -> 0 | K22: =TotalSupply*K$6*MAX(0,MIN(1,IF(K$11="Linear",('Linear Curves'!D16-'Linear Curves'!D$8)/('Linear Curves'!D$10),('Sigmoid Curves'!D16-'Sigmoid Curves'!D$8)/('Sigmoid Curves'!D$10)))) -> 0 | L22: =TotalSupply*L$6*MAX(0,MIN(1,IF(L$11="Linear",('Linear Curves'!F16-'Linear Curves'!F$8)/('Linear Curves'!F$10),('Sigmoid Curves'!F16-'Sigmoid Curves'!F$8)/('Sigmoid Curves'!F$10)))) -> 0 | M22: =TotalSupply*M$6*MAX(0,MIN(1,IF(M$11="Linear",('Linear Curves'!G16-'Linear Curves'!G$8)/('Linear Curves'!G$10),('Sigmoid Curves'!G16-'Sigmoid Curves'!G$8)/('Sigmoid Curves'!G$10)))) -> 0 | N22: =TotalSupply*N$6*MAX(0,MIN(1,IF(N$11="Linear",('Linear Curves'!H16-'Linear Curves'!H$8)/('Linear Curves'!H$10),('Sigmoid Curves'!H16-'Sigmoid Curves'!H$8)/('Sigmoid Curves'!H$10)))) -> 56000000 | O22: =TotalSupply*O$6*MAX(0,MIN(1,IF(O$11="Linear",('Linear Curves'!I16-'Linear Curves'!I$8)/('Linear Curves'!I$10),('Sigmoid Curves'!I16-'Sigmoid Curves'!I$8)/('Sigmoid Curves'!I$10)))) -> 24000000 | P22: =TotalSupply*P$6*MAX(0,MIN(1,IF(P$11="Linear",('Linear Curves'!I16-'Linear Curves'!I$8)/('Linear Curves'!I$10),('Sigmoid Curves'!I16-'Sigmoid Curves'!I$8)/('Sigmoid Curves'!I$10)))) -> 200000000 | Q22: =TotalSupply*Q$6*MAX(0,MIN(1,IF(Q$11="Linear",('Linear Curves'!J16-'Linear Curves'!J$8)/('Linear Curves'!J$10),('Sigmoid Curves'!J16-'Sigmoid Curves'!J$8)/('Sigmoid Curves'!J$10)))) -> 20000000 | R22: =TotalSupply*R$6*MAX(0,MIN(1,IF(R$11="Linear",('Linear Curves'!K16-'Linear Curves'!K$8)/('Linear Curves'!K$10),('Sigmoid Curves'!K16-'Sigmoid Curves'!K$8)/('Sigmoid Curves'!K$10)))) -> 28800000 | S22: =TotalSupply*S$6*MAX(0,MIN(1,IF(S$11="Linear",('Linear Curves'!L16-'Linear Curves'!L$8)/('Linear Curves'!L$10),('Sigmoid Curves'!L16-'Sigmoid Curves'!L$8)/('Sigmoid Curves'!L$10)))) -> 3200000
A23: 4 | B23: =MIN(1,((1-G$19)/(MATCH(100%,G$19:G1007,0)-1)*A23)+G$19) -> 0.10625 | C23: =B23-B22 -> 0.0203125 | D23: =G23-G22 -> 0.093333333 | E23: =((B23/B22)-1)*12 -> 2.8363636 | F23: =((H23/H22)-1)*12 -> 2.6987952 | G23: =H23/TotalSupply -> 0.50833333 | H23: =SUM(I23:AG23) -> 4.0666667e+08 | I23: =TotalSupply*I$6*MAX(0,MIN(1,IF(I$11="Linear",('Linear Curves'!B17-'Linear Curves'!B$8)/('Linear Curves'!B$10),('Sigmoid Curves'!B17-'Sigmoid Curves'!B$8)/('Sigmoid Curves'!B$10)))) -> 0 | J23: =TotalSupply*J$6*MAX(0,MIN(1,IF(J$11="Linear",('Linear Curves'!C17-'Linear Curves'!C$8)/('Linear Curves'!C$10),('Sigmoid Curves'!C17-'Sigmoid Curves'!C$8)/('Sigmoid Curves'!C$10)))) -> 0 | K23: =TotalSupply*K$6*MAX(0,MIN(1,IF(K$11="Linear",('Linear Curves'!D17-'Linear Curves'!D$8)/('Linear Curves'!D$10),('Sigmoid Curves'!D17-'Sigmoid Curves'!D$8)/('Sigmoid Curves'!D$10)))) -> 0 | L23: =TotalSupply*L$6*MAX(0,MIN(1,IF(L$11="Linear",('Linear Curves'!F17-'Linear Curves'!F$8)/('Linear Curves'!F$10),('Sigmoid Curves'!F17-'Sigmoid Curves'!F$8)/('Sigmoid Curves'!F$10)))) -> 0 | M23: =TotalSupply*M$6*MAX(0,MIN(1,IF(M$11="Linear",('Linear Curves'!G17-'Linear Curves'!G$8)/('Linear Curves'!G$10),('Sigmoid Curves'!G17-'Sigmoid Curves'!G$8)/('Sigmoid Curves'!G$10)))) -> 0 | N23: =TotalSupply*N$6*MAX(0,MIN(1,IF(N$11="Linear",('Linear Curves'!H17-'Linear Curves'!H$8)/('Linear Curves'!H$10),('Sigmoid Curves'!H17-'Sigmoid Curves'!H$8)/('Sigmoid Curves'!H$10)))) -> 56000000 | O23: =TotalSupply*O$6*MAX(0,MIN(1,IF(O$11="Linear",('Linear Curves'!I17-'Linear Curves'!I$8)/('Linear Curves'!I$10),('Sigmoid Curves'!I17-'Sigmoid Curves'!I$8)/('Sigmoid Curves'!I$10)))) -> 32000000 | P23: =TotalSupply*P$6*MAX(0,MIN(1,IF(P$11="Linear",('Linear Curves'!I17-'Linear Curves'!I$8)/('Linear Curves'!I$10),('Sigmoid Curves'!I17-'Sigmoid Curves'!I$8)/('Sigmoid Curves'!I$10)))) -> 2.6666667e+08 | Q23: =TotalSupply*Q$6*MAX(0,MIN(1,IF(Q$11="Linear",('Linear Curves'!J17-'Linear Curves'!J$8)/('Linear Curves'!J$10),('Sigmoid Curves'!J17-'Sigmoid Curves'!J$8)/('Sigmoid Curves'!J$10)))) -> 20000000 | R23: =TotalSupply*R$6*MAX(0,MIN(1,IF(R$11="Linear",('Linear Curves'!K17-'Linear Curves'!K$8)/('Linear Curves'!K$10),('Sigmoid Curves'!K17-'Sigmoid Curves'!K$8)/('Sigmoid Curves'!K$10)))) -> 28800000 | S23: =TotalSupply*S$6*MAX(0,MIN(1,IF(S$11="Linear",('Linear Curves'!L17-'Linear Curves'!L$8)/('Linear Curves'!L$10),('Sigmoid Curves'!L17-'Sigmoid Curves'!L$8)/('Sigmoid Curves'!L$10)))) -> 3200000
A24: 5 | B24: =MIN(1,((1-G$19)/(MATCH(100%,G$19:G1008,0)-1)*A24)+G$19) -> 0.1265625 | C24: =B24-B23 -> 0.0203125 | D24: =G24-G23 -> 0.093333333 | E24: =((B24/B23)-1)*12 -> 2.2941176 | F24: =((H24/H23)-1)*12 -> 2.2032787 | G24: =H24/TotalSupply -> 0.60166667 | H24: =SUM(I24:AG24) -> 4.8133333e+08 | I24: =TotalSupply*I$6*MAX(0,MIN(1,IF(I$11="Linear",('Linear Curves'!B18-'Linear Curves'!B$8)/('Linear Curves'!B$10),('Sigmoid Curves'!B18-'Sigmoid Curves'!B$8)/('Sigmoid Curves'!B$10)))) -> 0 | J24: =TotalSupply*J$6*MAX(0,MIN(1,IF(J$11="Linear",('Linear Curves'!C18-'Linear Curves'!C$8)/('Linear Curves'!C$10),('Sigmoid Curves'!C18-'Sigmoid Curves'!C$8)/('Sigmoid Curves'!C$10)))) -> 0 | K24: =TotalSupply*K$6*MAX(0,MIN(1,IF(K$11="Linear",('Linear Curves'!D18-'Linear Curves'!D$8)/('Linear Curves'!D$10),('Sigmoid Curves'!D18-'Sigmoid Curves'!D$8)/('Sigmoid Curves'!D$10)))) -> 0 | L24: =TotalSupply*L$6*MAX(0,MIN(1,IF(L$11="Linear",('Linear Curves'!F18-'Linear Curves'!F$8)/('Linear Curves'!F$10),('Sigmoid Curves'!F18-'Sigmoid Curves'!F$8)/('Sigmoid Curves'!F$10)))) -> 0 | M24: =TotalSupply*M$6*MAX(0,MIN(1,IF(M$11="Linear",('Linear Curves'!G18-'Linear Curves'!G$8)/('Linear Curves'!G$10),('Sigmoid Curves'!G18-'Sigmoid Curves'!G$8)/('Sigmoid Curves'!G$10)))) -> 0 | N24: =TotalSupply*N$6*MAX(0,MIN(1,IF(N$11="Linear",('Linear Curves'!H18-'Linear Curves'!H$8)/('Linear Curves'!H$10),('Sigmoid Curves'!H18-'Sigmoid Curves'!H$8)/('Sigmoid Curves'!H$10)))) -> 56000000 | O24: =TotalSupply*O$6*MAX(0,MIN(1,IF(O$11="Linear",('Linear Curves'!I18-'Linear Curves'!I$8)/('Linear Curves'!I$10),('Sigmoid Curves'!I18-'Sigmoid Curves'!I$8)/('Sigmoid Curves'!I$10)))) -> 40000000 | P24: =TotalSupply*P$6*MAX(0,MIN(1,IF(P$11="Linear",('Linear Curves'!I18-'Linear Curves'!I$8)/('Linear Curves'!I$10),('Sigmoid Curves'!I18-'Sigmoid Curves'!I$8)/('Sigmoid Curves'!I$10)))) -> 3.3333333e+08 | Q24: =TotalSupply*Q$6*MAX(0,MIN(1,IF(Q$11="Linear",('Linear Curves'!J18-'Linear Curves'!J$8)/('Linear Curves'!J$10),('Sigmoid Curves'!J18-'Sigmoid Curves'!J$8)/('Sigmoid Curves'!J$10)))) -> 20000000 | R24: =TotalSupply*R$6*MAX(0,MIN(1,IF(R$11="Linear",('Linear Curves'!K18-'Linear Curves'!K$8)/('Linear Curves'!K$10),('Sigmoid Curves'!K18-'Sigmoid Curves'!K$8)/('Sigmoid Curves'!K$10)))) -> 28800000 | S24: =TotalSupply*S$6*MAX(0,MIN(1,IF(S$11="Linear",('Linear Curves'!L18-'Linear Curves'!L$8)/('Linear Curves'!L$10),('Sigmoid Curves'!L18-'Sigmoid Curves'!L$8)/('Sigmoid Curves'!L$10)))) -> 3200000
A25: 6 | B25: =MIN(1,((1-G$19)/(MATCH(100%,G$19:G1009,0)-1)*A25)+G$19) -> 0.146875 | C25: =B25-B24 -> 0.0203125 | D25: =G25-G24 -> 0.10435133 | E25: =((B25/B24)-1)*12 -> 1.9259259 | F25: =((H25/H24)-1)*12 -> 2.0812454 | G25: =H25/TotalSupply -> 0.706018 | H25: =SUM(I25:AG25) -> 5.648144e+08 | I25: =TotalSupply*I$6*MAX(0,MIN(1,IF(I$11="Linear",('Linear Curves'!B19-'Linear Curves'!B$8)/('Linear Curves'!B$10),('Sigmoid Curves'!B19-'Sigmoid Curves'!B$8)/('Sigmoid Curves'!B$10)))) -> 0 | J25: =TotalSupply*J$6*MAX(0,MIN(1,IF(J$11="Linear",('Linear Curves'!C19-'Linear Curves'!C$8)/('Linear Curves'!C$10),('Sigmoid Curves'!C19-'Sigmoid Curves'!C$8)/('Sigmoid Curves'!C$10)))) -> 0 | K25: =TotalSupply*K$6*MAX(0,MIN(1,IF(K$11="Linear",('Linear Curves'!D19-'Linear Curves'!D$8)/('Linear Curves'!D$10),('Sigmoid Curves'!D19-'Sigmoid Curves'!D$8)/('Sigmoid Curves'!D$10)))) -> 8000000 | L25: =TotalSupply*L$6*MAX(0,MIN(1,IF(L$11="Linear",('Linear Curves'!F19-'Linear Curves'!F$8)/('Linear Curves'!F$10),('Sigmoid Curves'!F19-'Sigmoid Curves'!F$8)/('Sigmoid Curves'!F$10)))) -> 0 | M25: =TotalSupply*M$6*MAX(0,MIN(1,IF(M$11="Linear",('Linear Curves'!G19-'Linear Curves'!G$8)/('Linear Curves'!G$10),('Sigmoid Curves'!G19-'Sigmoid Curves'!G$8)/('Sigmoid Curves'!G$10)))) -> 814399.33 | N25: =TotalSupply*N$6*MAX(0,MIN(1,IF(N$11="Linear",('Linear Curves'!H19-'Linear Curves'!H$8)/('Linear Curves'!H$10),('Sigmoid Curves'!H19-'Sigmoid Curves'!H$8)/('Sigmoid Curves'!H$10)))) -> 56000000 | O25: =TotalSupply*O$6*MAX(0,MIN(1,IF(O$11="Linear",('Linear Curves'!I19-'Linear Curves'!I$8)/('Linear Curves'!I$10),('Sigmoid Curves'!I19-'Sigmoid Curves'!I$8)/('Sigmoid Curves'!I$10)))) -> 48000000 | P25: =TotalSupply*P$6*MAX(0,MIN(1,IF(P$11="Linear",('Linear Curves'!I19-'Linear Curves'!I$8)/('Linear Curves'!I$10),('Sigmoid Curves'!I19-'Sigmoid Curves'!I$8)/('Sigmoid Curves'!I$10)))) -> 400000000 | Q25: =TotalSupply*Q$6*MAX(0,MIN(1,IF(Q$11="Linear",('Linear Curves'!J19-'Linear Curves'!J$8)/('Linear Curves'!J$10),('Sigmoid Curves'!J19-'Sigmoid Curves'!J$8)/('Sigmoid Curves'!J$10)))) -> 20000000 | R25: =TotalSupply*R$6*MAX(0,MIN(1,IF(R$11="Linear",('Linear Curves'!K19-'Linear Curves'!K$8)/('Linear Curves'!K$10),('Sigmoid Curves'!K19-'Sigmoid Curves'!K$8)/('Sigmoid Curves'!K$10)))) -> 28800000 | S25: =TotalSupply*S$6*MAX(0,MIN(1,IF(S$11="Linear",('Linear Curves'!L19-'Linear Curves'!L$8)/('Linear Curves'!L$10),('Sigmoid Curves'!L19-'Sigmoid Curves'!L$8)/('Sigmoid Curves'!L$10)))) -> 3200000
A26: 7 | B26: =MIN(1,((1-G$19)/(MATCH(100%,G$19:G1010,0)-1)*A26)+G$19) -> 0.1671875 | C26: =B26-B25 -> 0.0203125 | D26: =G26-G25 -> 0.001844089 | E26: =((B26/B25)-1)*12 -> 1.6595745 | F26: =((H26/H25)-1)*12 -> 0.031343489 | G26: =H26/TotalSupply -> 0.70786209 | H26: =SUM(I26:AG26) -> 5.6628967e+08 | I26: =TotalSupply*I$6*MAX(0,MIN(1,IF(I$11="Linear",('Linear Curves'!B20-'Linear Curves'!B$8)/('Linear Curves'!B$10),('Sigmoid Curves'!B20-'Sigmoid Curves'!B$8)/('Sigmoid Curves'!B$10)))) -> 0 | J26: =TotalSupply*J$6*MAX(0,MIN(1,IF(J$11="Linear",('Linear Curves'!C20-'Linear Curves'!C$8)/('Linear Curves'!C$10),('Sigmoid Curves'!C20-'Sigmoid Curves'!C$8)/('Sigmoid Curves'!C$10)))) -> 0 | K26: =TotalSupply*K$6*MAX(0,MIN(1,IF(K$11="Linear",('Linear Curves'!D20-'Linear Curves'!D$8)/('Linear Curves'!D$10),('Sigmoid Curves'!D20-'Sigmoid Curves'!D$8)/('Sigmoid Curves'!D$10)))) -> 9333333.3 | L26: =TotalSupply*L$6*MAX(0,MIN(1,IF(L$11="Linear",('Linear Curves'!F20-'Linear Curves'!F$8)/('Linear Curves'!F$10),('Sigmoid Curves'!F20-'Sigmoid Curves'!F$8)/('Sigmoid Curves'!F$10)))) -> 0 | M26: =TotalSupply*M$6*MAX(0,MIN(1,IF(M$11="Linear",('Linear Curves'!G20-'Linear Curves'!G$8)/('Linear Curves'!G$10),('Sigmoid Curves'!G20-'Sigmoid Curves'!G$8)/('Sigmoid Curves'!G$10)))) -> 956337.17 | N26: =TotalSupply*N$6*MAX(0,MIN(1,IF(N$11="Linear",('Linear Curves'!H20-'Linear Curves'!H$8)/('Linear Curves'!H$10),('Sigmoid Curves'!H20-'Sigmoid Curves'!H$8)/('Sigmoid Curves'!H$10)))) -> 56000000 | O26: =TotalSupply*O$6*MAX(0,MIN(1,IF(O$11="Linear",('Linear Curves'!I20-'Linear Curves'!I$8)/('Linear Curves'!I$10),('Sigmoid Curves'!I20-'Sigmoid Curves'!I$8)/('Sigmoid Curves'!I$10)))) -> 48000000 | P26: =TotalSupply*P$6*MAX(0,MIN(1,IF(P$11="Linear",('Linear Curves'!I20-'Linear Curves'!I$8)/('Linear Curves'!I$10),('Sigmoid Curves'!I20-'Sigmoid Curves'!I$8)/('Sigmoid Curves'!I$10)))) -> 400000000 | Q26: =TotalSupply*Q$6*MAX(0,MIN(1,IF(Q$11="Linear",('Linear Curves'!J20-'Linear Curves'!J$8)/('Linear Curves'!J$10),('Sigmoid Curves'!J20-'Sigmoid Curves'!J$8)/('Sigmoid Curves'!J$10)))) -> 20000000 | R26: =TotalSupply*R$6*MAX(0,MIN(1,IF(R$11="Linear",('Linear Curves'!K20-'Linear Curves'!K$8)/('Linear Curves'!K$10),('Sigmoid Curves'!K20-'Sigmoid Curves'!K$8)/('Sigmoid Curves'!K$10)))) -> 28800000 | S26: =TotalSupply*S$6*MAX(0,MIN(1,IF(S$11="Linear",('Linear Curves'!L20-'Linear Curves'!L$8)/('Linear Curves'!L$10),('Sigmoid Curves'!L20-'Sigmoid Curves'!L$8)/('Sigmoid Curves'!L$10)))) -> 3200000
A27: 8 | B27: =MIN(1,((1-G$19)/(MATCH(100%,G$19:G1011,0)-1)*A27)+G$19) -> 0.1875 | C27: =B27-B26 -> 0.0203125 | D27: =G27-G26 -> 0.0018656361 | E27: =((B27/B26)-1)*12 -> 1.4579439 | F27: =((H27/H26)-1)*12 -> 0.031627112 | G27: =H27/TotalSupply -> 0.70972772 | H27: =SUM(I27:AG27) -> 5.6778218e+08 | I27: =TotalSupply*I$6*MAX(0,MIN(1,IF(I$11="Linear",('Linear Curves'!B21-'Linear Curves'!B$8)/('Linear Curves'!B$10),('Sigmoid Curves'!B21-'Sigmoid Curves'!B$8)/('Sigmoid Curves'!B$10)))) -> 0 | J27: =TotalSupply*J$6*MAX(0,MIN(1,IF(J$11="Linear",('Linear Curves'!C21-'Linear Curves'!C$8)/('Linear Curves'!C$10),('Sigmoid Curves'!C21-'Sigmoid Curves'!C$8)/('Sigmoid Curves'!C$10)))) -> 0 | K27: =TotalSupply*K$6*MAX(0,MIN(1,IF(K$11="Linear",('Linear Curves'!D21-'Linear Curves'!D$8)/('Linear Curves'!D$10),('Sigmoid Curves'!D21-'Sigmoid Curves'!D$8)/('Sigmoid Curves'!D$10)))) -> 10666667 | L27: =TotalSupply*L$6*MAX(0,MIN(1,IF(L$11="Linear",('Linear Curves'!F21-'Linear Curves'!F$8)/('Linear Curves'!F$10),('Sigmoid Curves'!F21-'Sigmoid Curves'!F$8)/('Sigmoid Curves'!F$10)))) -> 0 | M27: =TotalSupply*M$6*MAX(0,MIN(1,IF(M$11="Linear",('Linear Curves'!G21-'Linear Curves'!G$8)/('Linear Curves'!G$10),('Sigmoid Curves'!G21-'Sigmoid Curves'!G$8)/('Sigmoid Curves'!G$10)))) -> 1115512.7 | N27: =TotalSupply*N$6*MAX(0,MIN(1,IF(N$11="Linear",('Linear Curves'!H21-'Linear Curves'!H$8)/('Linear Curves'!H$10),('Sigmoid Curves'!H21-'Sigmoid Curves'!H$8)/('Sigmoid Curves'!H$10)))) -> 56000000 | O27: =TotalSupply*O$6*MAX(0,MIN(1,IF(O$11="Linear",('Linear Curves'!I21-'Linear Curves'!I$8)/('Linear Curves'!I$10),('Sigmoid Curves'!I21-'Sigmoid Curves'!I$8)/('Sigmoid Curves'!I$10)))) -> 48000000 | P27: =TotalSupply*P$6*MAX(0,MIN(1,IF(P$11="Linear",('Linear Curves'!I21-'Linear Curves'!I$8)/('Linear Curves'!I$10),('Sigmoid Curves'!I21-'Sigmoid Curves'!I$8)/('Sigmoid Curves'!I$10)))) -> 400000000 | Q27: =TotalSupply*Q$6*MAX(0,MIN(1,IF(Q$11="Linear",('Linear Curves'!J21-'Linear Curves'!J$8)/('Linear Curves'!J$10),('Sigmoid Curves'!J21-'Sigmoid Curves'!J$8)/('Sigmoid Curves'!J$10)))) -> 20000000 | R27: =TotalSupply*R$6*MAX(0,MIN(1,IF(R$11="Linear",('Linear Curves'!K21-'Linear Curves'!K$8)/('Linear Curves'!K$10),('Sigmoid Curves'!K21-'Sigmoid Curves'!K$8)/('Sigmoid Curves'!K$10)))) -> 28800000 | S27: =TotalSupply*S$6*MAX(0,MIN(1,IF(S$11="Linear",('Linear Curves'!L21-'Linear Curves'!L$8)/('Linear Curves'!L$10),('Sigmoid Curves'!L21-'Sigmoid Curves'!L$8)/('Sigmoid Curves'!L$10)))) -> 3200000
A28: 9 | B28: =MIN(1,((1-G$19)/(MATCH(100%,G$19:G1012,0)-1)*A28)+G$19) -> 0.2078125 | C28: =B28-B27 -> 0.0203125 | D28: =G28-G27 -> 0.0018866623 | E28: =((B28/B27)-1)*12 -> 1.3 | F28: =((H28/H27)-1)*12 -> 0.031899483 | G28: =H28/TotalSupply -> 0.71161439 | H28: =SUM(I28:AG28) -> 5.6929151e+08 | I28: =TotalSupply*I$6*MAX(0,MIN(1,IF(I$11="Linear",('Linear Curves'!B22-'Linear Curves'!B$8)/('Linear Curves'!B$10),('Sigmoid Curves'!B22-'Sigmoid Curves'!B$8)/('Sigmoid Curves'!B$10)))) -> 0 | J28: =TotalSupply*J$6*MAX(0,MIN(1,IF(J$11="Linear",('Linear Curves'!C22-'Linear Curves'!C$8)/('Linear Curves'!C$10),('Sigmoid Curves'!C22-'Sigmoid Curves'!C$8)/('Sigmoid Curves'!C$10)))) -> 0 | K28: =TotalSupply*K$6*MAX(0,MIN(1,IF(K$11="Linear",('Linear Curves'!D22-'Linear Curves'!D$8)/('Linear Curves'!D$10),('Sigmoid Curves'!D22-'Sigmoid Curves'!D$8)/('Sigmoid Curves'!D$10)))) -> 12000000 | L28: =TotalSupply*L$6*MAX(0,MIN(1,IF(L$11="Linear",('Linear Curves'!F22-'Linear Curves'!F$8)/('Linear Curves'!F$10),('Sigmoid Curves'!F22-'Sigmoid Curves'!F$8)/('Sigmoid Curves'!F$10)))) -> 0 | M28: =TotalSupply*M$6*MAX(0,MIN(1,IF(M$11="Linear",('Linear Curves'!G22-'Linear Curves'!G$8)/('Linear Curves'!G$10),('Sigmoid Curves'!G22-'Sigmoid Curves'!G$8)/('Sigmoid Curves'!G$10)))) -> 1291509.2 | N28: =TotalSupply*N$6*MAX(0,MIN(1,IF(N$11="Linear",('Linear Curves'!H22-'Linear Curves'!H$8)/('Linear Curves'!H$10),('Sigmoid Curves'!H22-'Sigmoid Curves'!H$8)/('Sigmoid Curves'!H$10)))) -> 56000000 | O28: =TotalSupply*O$6*MAX(0,MIN(1,IF(O$11="Linear",('Linear Curves'!I22-'Linear Curves'!I$8)/('Linear Curves'!I$10),('Sigmoid Curves'!I22-'Sigmoid Curves'!I$8)/('Sigmoid Curves'!I$10)))) -> 48000000 | P28: =TotalSupply*P$6*MAX(0,MIN(1,IF(P$11="Linear",('Linear Curves'!I22-'Linear Curves'!I$8)/('Linear Curves'!I$10),('Sigmoid Curves'!I22-'Sigmoid Curves'!I$8)/('Sigmoid Curves'!I$10)))) -> 400000000 | Q28: =TotalSupply*Q$6*MAX(0,MIN(1,IF(Q$11="Linear",('Linear Curves'!J22-'Linear Curves'!J$8)/('Linear Curves'!J$10),('Sigmoid Curves'!J22-'Sigmoid Curves'!J$8)/('Sigmoid Curves'!J$10)))) -> 20000000 | R28: =TotalSupply*R$6*MAX(0,MIN(1,IF(R$11="Linear",('Linear Curves'!K22-'Linear Curves'!K$8)/('Linear Curves'!K$10),('Sigmoid Curves'!K22-'Sigmoid Curves'!K$8)/('Sigmoid Curves'!K$10)))) -> 28800000 | S28: =TotalSupply*S$6*MAX(0,MIN(1,IF(S$11="Linear",('Linear Curves'!L22-'Linear Curves'!L$8)/('Linear Curves'!L$10),('Sigmoid Curves'!L22-'Sigmoid Curves'!L$8)/('Sigmoid Curves'!L$10)))) -> 3200000
A29: 10 | B29: =MIN(1,((1-G$19)/(MATCH(100%,G$19:G1013,0)-1)*A29)+G$19) -> 0.228125 | C29: =B29-B28 -> 0.0203125 | D29: =G29-G28 -> 0.0019061339 | E29: =((B29/B28)-1)*12 -> 1.1729323 | F29: =((H29/H28)-1)*12 -> 0.03214326 | G29: =H29/TotalSupply -> 0.71352052 | H29: =SUM(I29:AG29) -> 5.7081642e+08 | I29: =TotalSupply*I$6*MAX(0,MIN(1,IF(I$11="Linear",('Linear Curves'!B23-'Linear Curves'!B$8)/('Linear Curves'!B$10),('Sigmoid Curves'!B23-'Sigmoid Curves'!B$8)/('Sigmoid Curves'!B$10)))) -> 0 | J29: =TotalSupply*J$6*MAX(0,MIN(1,IF(J$11="Linear",('Linear Curves'!C23-'Linear Curves'!C$8)/('Linear Curves'!C$10),('Sigmoid Curves'!C23-'Sigmoid Curves'!C$8)/('Sigmoid Curves'!C$10)))) -> 0 | K29: =TotalSupply*K$6*MAX(0,MIN(1,IF(K$11="Linear",('Linear Curves'!D23-'Linear Curves'!D$8)/('Linear Curves'!D$10),('Sigmoid Curves'!D23-'Sigmoid Curves'!D$8)/('Sigmoid Curves'!D$10)))) -> 13333333 | L29: =TotalSupply*L$6*MAX(0,MIN(1,IF(L$11="Linear",('Linear Curves'!F23-'Linear Curves'!F$8)/('Linear Curves'!F$10),('Sigmoid Curves'!F23-'Sigmoid Curves'!F$8)/('Sigmoid Curves'!F$10)))) -> 0 | M29: =TotalSupply*M$6*MAX(0,MIN(1,IF(M$11="Linear",('Linear Curves'!G23-'Linear Curves'!G$8)/('Linear Curves'!G$10),('Sigmoid Curves'!G23-'Sigmoid Curves'!G$8)/('Sigmoid Curves'!G$10)))) -> 1483083 | N29: =TotalSupply*N$6*MAX(0,MIN(1,IF(N$11="Linear",('Linear Curves'!H23-'Linear Curves'!H$8)/('Linear Curves'!H$10),('Sigmoid Curves'!H23-'Sigmoid Curves'!H$8)/('Sigmoid Curves'!H$10)))) -> 56000000 | O29: =TotalSupply*O$6*MAX(0,MIN(1,IF(O$11="Linear",('Linear Curves'!I23-'Linear Curves'!I$8)/('Linear Curves'!I$10),('Sigmoid Curves'!I23-'Sigmoid Curves'!I$8)/('Sigmoid Curves'!I$10)))) -> 48000000 | P29: =TotalSupply*P$6*MAX(0,MIN(1,IF(P$11="Linear",('Linear Curves'!I23-'Linear Curves'!I$8)/('Linear Curves'!I$10),('Sigmoid Curves'!I23-'Sigmoid Curves'!I$8)/('Sigmoid Curves'!I$10)))) -> 400000000 | Q29: =TotalSupply*Q$6*MAX(0,MIN(1,IF(Q$11="Linear",('Linear Curves'!J23-'Linear Curves'!J$8)/('Linear Curves'!J$10),('Sigmoid Curves'!J23-'Sigmoid Curves'!J$8)/('Sigmoid Curves'!J$10)))) -> 20000000 | R29: =TotalSupply*R$6*MAX(0,MIN(1,IF(R$11="Linear",('Linear Curves'!K23-'Linear Curves'!K$8)/('Linear Curves'!K$10),('Sigmoid Curves'!K23-'Sigmoid Curves'!K$8)/('Sigmoid Curves'!K$10)))) -> 28800000 | S29: =TotalSupply*S$6*MAX(0,MIN(1,IF(S$11="Linear",('Linear Curves'!L23-'Linear Curves'!L$8)/('Linear Curves'!L$10),('Sigmoid Curves'!L23-'Sigmoid Curves'!L$8)/('Sigmoid Curves'!L$10)))) -> 3200000
A30: 11 | B30: =MIN(1,((1-G$19)/(MATCH(100%,G$19:G1014,0)-1)*A30)+G$19) -> 0.2484375 | C30: =B30-B29 -> 0.0203125 | D30: =G30-G29 -> 0.0019229298 | E30: =((B30/B29)-1)*12 -> 1.0684932 | F30: =((H30/H29)-1)*12 -> 0.032339865 | G30: =H30/TotalSupply -> 0.71544345 | H30: =SUM(I30:AG30) -> 5.7235476e+08 | I30: =TotalSupply*I$6*MAX(0,MIN(1,IF(I$11="Linear",('Linear Curves'!B24-'Linear Curves'!B$8)/('Linear Curves'!B$10),('Sigmoid Curves'!B24-'Sigmoid Curves'!B$8)/('Sigmoid Curves'!B$10)))) -> 0 | J30: =TotalSupply*J$6*MAX(0,MIN(1,IF(J$11="Linear",('Linear Curves'!C24-'Linear Curves'!C$8)/('Linear Curves'!C$10),('Sigmoid Curves'!C24-'Sigmoid Curves'!C$8)/('Sigmoid Curves'!C$10)))) -> 0 | K30: =TotalSupply*K$6*MAX(0,MIN(1,IF(K$11="Linear",('Linear Curves'!D24-'Linear Curves'!D$8)/('Linear Curves'!D$10),('Sigmoid Curves'!D24-'Sigmoid Curves'!D$8)/('Sigmoid Curves'!D$10)))) -> 14666667 | L30: =TotalSupply*L$6*MAX(0,MIN(1,IF(L$11="Linear",('Linear Curves'!F24-'Linear Curves'!F$8)/('Linear Curves'!F$10),('Sigmoid Curves'!F24-'Sigmoid Curves'!F$8)/('Sigmoid Curves'!F$10)))) -> 0 | M30: =TotalSupply*M$6*MAX(0,MIN(1,IF(M$11="Linear",('Linear Curves'!G24-'Linear Curves'!G$8)/('Linear Curves'!G$10),('Sigmoid Curves'!G24-'Sigmoid Curves'!G$8)/('Sigmoid Curves'!G$10)))) -> 1688093.5 | N30: =TotalSupply*N$6*MAX(0,MIN(1,IF(N$11="Linear",('Linear Curves'!H24-'Linear Curves'!H$8)/('Linear Curves'!H$10),('Sigmoid Curves'!H24-'Sigmoid Curves'!H$8)/('Sigmoid Curves'!H$10)))) -> 56000000 | O30: =TotalSupply*O$6*MAX(0,MIN(1,IF(O$11="Linear",('Linear Curves'!I24-'Linear Curves'!I$8)/('Linear Curves'!I$10),('Sigmoid Curves'!I24-'Sigmoid Curves'!I$8)/('Sigmoid Curves'!I$10)))) -> 48000000 | P30: =TotalSupply*P$6*MAX(0,MIN(1,IF(P$11="Linear",('Linear Curves'!I24-'Linear Curves'!I$8)/('Linear Curves'!I$10),('Sigmoid Curves'!I24-'Sigmoid Curves'!I$8)/('Sigmoid Curves'!I$10)))) -> 400000000 | Q30: =TotalSupply*Q$6*MAX(0,MIN(1,IF(Q$11="Linear",('Linear Curves'!J24-'Linear Curves'!J$8)/('Linear Curves'!J$10),('Sigmoid Curves'!J24-'Sigmoid Curves'!J$8)/('Sigmoid Curves'!J$10)))) -> 20000000 | R30: =TotalSupply*R$6*MAX(0,MIN(1,IF(R$11="Linear",('Linear Curves'!K24-'Linear Curves'!K$8)/('Linear Curves'!K$10),('Sigmoid Curves'!K24-'Sigmoid Curves'!K$8)/('Sigmoid Curves'!K$10)))) -> 28800000 | S30: =TotalSupply*S$6*MAX(0,MIN(1,IF(S$11="Linear",('Linear Curves'!L24-'Linear Curves'!L$8)/('Linear Curves'!L$10),('Sigmoid Curves'!L24-'Sigmoid Curves'!L$8)/('Sigmoid Curves'!L$10)))) -> 3200000
A31: 12 | B31: =MIN(1,((1-G$19)/(MATCH(100%,G$19:G1015,0)-1)*A31)+G$19) -> 0.26875 | C31: =B31-B30 -> 0.0203125 | D31: =G31-G30 -> 0.055434846 | E31: =((B31/B30)-1)*12 -> 0.98113208 | F31: =((H31/H30)-1)*12 -> 0.92979836 | G31: =H31/TotalSupply -> 0.7708783 | H31: =SUM(I31:AG31) -> 6.1670264e+08 | I31: =TotalSupply*I$6*MAX(0,MIN(1,IF(I$11="Linear",('Linear Curves'!B25-'Linear Curves'!B$8)/('Linear Curves'!B$10),('Sigmoid Curves'!B25-'Sigmoid Curves'!B$8)/('Sigmoid Curves'!B$10)))) -> 19982378 | J31: =TotalSupply*J$6*MAX(0,MIN(1,IF(J$11="Linear",('Linear Curves'!C25-'Linear Curves'!C$8)/('Linear Curves'!C$10),('Sigmoid Curves'!C25-'Sigmoid Curves'!C$8)/('Sigmoid Curves'!C$10)))) -> 17676719 | K31: =TotalSupply*K$6*MAX(0,MIN(1,IF(K$11="Linear",('Linear Curves'!D25-'Linear Curves'!D$8)/('Linear Curves'!D$10),('Sigmoid Curves'!D25-'Sigmoid Curves'!D$8)/('Sigmoid Curves'!D$10)))) -> 16000000 | L31: =TotalSupply*L$6*MAX(0,MIN(1,IF(L$11="Linear",('Linear Curves'!F25-'Linear Curves'!F$8)/('Linear Curves'!F$10),('Sigmoid Curves'!F25-'Sigmoid Curves'!F$8)/('Sigmoid Curves'!F$10)))) -> 5140013.2 | M31: =TotalSupply*M$6*MAX(0,MIN(1,IF(M$11="Linear",('Linear Curves'!G25-'Linear Curves'!G$8)/('Linear Curves'!G$10),('Sigmoid Curves'!G25-'Sigmoid Curves'!G$8)/('Sigmoid Curves'!G$10)))) -> 1903525.6 | N31: =TotalSupply*N$6*MAX(0,MIN(1,IF(N$11="Linear",('Linear Curves'!H25-'Linear Curves'!H$8)/('Linear Curves'!H$10),('Sigmoid Curves'!H25-'Sigmoid Curves'!H$8)/('Sigmoid Curves'!H$10)))) -> 56000000 | O31: =TotalSupply*O$6*MAX(0,MIN(1,IF(O$11="Linear",('Linear Curves'!I25-'Linear Curves'!I$8)/('Linear Curves'!I$10),('Sigmoid Curves'!I25-'Sigmoid Curves'!I$8)/('Sigmoid Curves'!I$10)))) -> 48000000 | P31: =TotalSupply*P$6*MAX(0,MIN(1,IF(P$11="Linear",('Linear Curves'!I25-'Linear Curves'!I$8)/('Linear Curves'!I$10),('Sigmoid Curves'!I25-'Sigmoid Curves'!I$8)/('Sigmoid Curves'!I$10)))) -> 400000000 | Q31: =TotalSupply*Q$6*MAX(0,MIN(1,IF(Q$11="Linear",('Linear Curves'!J25-'Linear Curves'!J$8)/('Linear Curves'!J$10),('Sigmoid Curves'!J25-'Sigmoid Curves'!J$8)/('Sigmoid Curves'!J$10)))) -> 20000000 | R31: =TotalSupply*R$6*MAX(0,MIN(1,IF(R$11="Linear",('Linear Curves'!K25-'Linear Curves'!K$8)/('Linear Curves'!K$10),('Sigmoid Curves'!K25-'Sigmoid Curves'!K$8)/('Sigmoid Curves'!K$10)))) -> 28800000 | S31: =TotalSupply*S$6*MAX(0,MIN(1,IF(S$11="Linear",('Linear Curves'!L25-'Linear Curves'!L$8)/('Linear Curves'!L$10),('Sigmoid Curves'!L25-'Sigmoid Curves'!L$8)/('Sigmoid Curves'!L$10)))) -> 3200000
... A79: 60 | B79: =MIN(1,((1-G$19)/(MATCH(100%,G$19:G1063,0)-1)*A79)+G$19) -> 1 | C79: =B79-B78 -> 0 | D79: =G79-G78 -> 0 | E79: =((B79/B78)-1)*12 -> 0 | F79: =((H79/H78)-1)*12 -> 0 | G79: =H79/TotalSupply -> 1 | H79: =SUM(I79:AG79) -> 800000000 | I79: =TotalSupply*I$6*MAX(0,MIN(1,IF(I$11="Linear",('Linear Curves'!B73-'Linear Curves'!B$8)/('Linear Curves'!B$10),('Sigmoid Curves'!B73-'Sigmoid Curves'!B$8)/('Sigmoid Curves'!B$10)))) -> 104000000 | J79: =TotalSupply*J$6*MAX(0,MIN(1,IF(J$11="Linear",('Linear Curves'!C73-'Linear Curves'!C$8)/('Linear Curves'!C$10),('Sigmoid Curves'!C73-'Sigmoid Curves'!C$8)/('Sigmoid Curves'!C$10)))) -> 92000000 | K79: =TotalSupply*K$6*MAX(0,MIN(1,IF(K$11="Linear",('Linear Curves'!D73-'Linear Curves'!D$8)/('Linear Curves'!D$10),('Sigmoid Curves'!D73-'Sigmoid Curves'!D$8)/('Sigmoid Curves'!D$10)))) -> 32000000 | L79: =TotalSupply*L$6*MAX(0,MIN(1,IF(L$11="Linear",('Linear Curves'!F73-'Linear Curves'!F$8)/('Linear Curves'!F$10),('Sigmoid Curves'!F73-'Sigmoid Curves'!F$8)/('Sigmoid Curves'!F$10)))) -> 12000000 | M79: =TotalSupply*M$6*MAX(0,MIN(1,IF(M$11="Linear",('Linear Curves'!G73-'Linear Curves'!G$8)/('Linear Curves'!G$10),('Sigmoid Curves'!G73-'Sigmoid Curves'!G$8)/('Sigmoid Curves'!G$10)))) -> 4000000 | N79: =TotalSupply*N$6*MAX(0,MIN(1,IF(N$11="Linear",('Linear Curves'!H73-'Linear Curves'!H$8)/('Linear Curves'!H$10),('Sigmoid Curves'!H73-'Sigmoid Curves'!H$8)/('Sigmoid Curves'!H$10)))) -> 56000000 | O79: =TotalSupply*O$6*MAX(0,MIN(1,IF(O$11="Linear",('Linear Curves'!I73-'Linear Curves'!I$8)/('Linear Curves'!I$10),('Sigmoid Curves'!I73-'Sigmoid Curves'!I$8)/('Sigmoid Curves'!I$10)))) -> 48000000 | P79: =TotalSupply*P$6*MAX(0,MIN(1,IF(P$11="Linear",('Linear Curves'!I73-'Linear Curves'!I$8)/('Linear Curves'!I$10),('Sigmoid Curves'!I73-'Sigmoid Curves'!I$8)/('Sigmoid Curves'!I$10)))) -> 400000000 | Q79: =TotalSupply*Q$6*MAX(0,MIN(1,IF(Q$11="Linear",('Linear Curves'!J73-'Linear Curves'!J$8)/('Linear Curves'!J$10),('Sigmoid Curves'!J73-'Sigmoid Curves'!J$8)/('Sigmoid Curves'!J$10)))) -> 20000000 | R79: =TotalSupply*R$6*MAX(0,MIN(1,IF(R$11="Linear",('Linear Curves'!K73-'Linear Curves'!K$8)/('Linear Curves'!K$10),('Sigmoid Curves'!K73-'Sigmoid Curves'!K$8)/('Sigmoid Curves'!K$10)))) -> 28800000 | S79: =TotalSupply*S$6*MAX(0,MIN(1,IF(S$11="Linear",('Linear Curves'!L73-'Linear Curves'!L$8)/('Linear Curves'!L$10),('Sigmoid Curves'!L73-'Sigmoid Curves'!L$8)/('Sigmoid Curves'!L$10)))) -> 3200000

Sheet Airdrop
A1: Year | B1: Purpose | C1: Tokens Distributed Annually | D1: Tokens Distributed Monthly
A2: 1 | B2: Attract Early Users | C2: 2666666 | D2: 222222
A3: 2 | B3: Build Community | C3: 2666666 | D3: 222222
A4: 3 | B4: Strengthen Engagement | C4: 2666666 | D4: 222222
A5: 4 | B5: Sustain Growth | C5: 1333333 | D5: 111111
A6: 5 | B6: Expand Network | C6: 1333333 | D6: 111111
A7: 6 | B7: Reward Contributors | C7: 1333333 | D7: 111111
A8: 7 | B8: Global Scale | C8: 1333333 | D8: 111111
A9: 8 | B9: Maintain Engagement | C9: 1333333 | D9: 111111
A10: 9 | B10: Grow Developer Base | C10: 1333333 | D10: 111111
A11: 10 | B11: Focus on New Markets | C11: 1333333 | D11: 111111
A12: 11 | B12: Support Partnerships | C12: 1333333 | D12: 111111
A13: 12 | B13: Finalize Adoption Efforts | C13: 1333333 | D13: 111111
A16: Explanation: First 3 Years (1% Allocation): Total Tokens: 8,000,000. Annual Distribution: 2,666,666 tokens/year. Remaining 9 Years (1.5% Allocation): Total Tokens: 12,000,000. Annual Distribution: 1,333,333 tokens/year. First 3 Years: 222,222.22 tokens per month. Next 9 Years: 111,111.11 tokens per month.

Sheet Linear Curves
A1: ='Supply (Allocation & Emissions)'!H5 -> Role | B1: ='Supply (Allocation & Emissions)'!I5 -> Team | C1: ='Supply (Allocation & Emissions)'!J5 -> Foundation | D1: =#REF! -> #REF! | E1: ='Supply (Allocation & Emissions)'!L5 -> Private Investors | F1: ='Supply (Allocation & Emissions)'!M5 -> Public rounds | G1: ='Supply (Allocation & Emissions)'!N5 -> Community Rewards | H1: =#REF! -> #REF! | I1: ='Supply (Allocation & Emissions)'!Q5 -> Air drops | J1: =#REF! -> #REF! | K1: ='Supply (Allocation & Emissions)'!P5 -> Staking | L1: ='Supply (Allocation & Emissions)'!S5 -> Testnet Incentive | M1: =#REF! -> #REF! | N1: ='Supply (Allocation & Emissions)'!T5 -> 0 | O1: ='Supply (Allocation & Emissions)'!U5 -> 0 | P1: ='Supply (Allocation & Emissions)'!V5 -> 0 | Q1: ='Supply (Allocation & Emissions)'!W5 -> 0 | R1: ='Supply (Allocation & Emissions)'!X5 -> 0 | S1: ='Supply (Allocation & Emissions)'!Y5 -> 0 | T1: ='Supply (Allocation & Emissions)'!Z5 -> 0 | U1: ='Supply (Allocation & Emissions)'!AA5 -> 0 | ... W1: ='Supply (Allocation & Emissions)'!AC5 -> 0
A2: ='Supply (Allocation & Emissions)'!H7 -> Vesting Months | B2: ='Supply (Allocation & Emissions)'!I7 -> 48 | C2: ='Supply (Allocation & Emissions)'!J7 -> 48 | D2: ='Supply (Allocation & Emissions)'!K7 -> 24 | E2: =#REF! -> #REF! | F2: ='Supply (Allocation & Emissions)'!L7 -> 36 | G2: ='Supply (Allocation & Emissions)'!M7 -> 24 | H2: ='Supply (Allocation & Emissions)'!N7 -> 2 | I2: ='Supply (Allocation & Emissions)'!P7 -> 6 | J2: ='Supply (Allocation & Emissions)'!Q7 -> 0 | K2: ='Supply (Allocation & Emissions)'!R7 -> 2 | L2: ='Supply (Allocation & Emissions)'!S7 -> 2 | M2: =#REF! -> #REF! | N2: ='Supply (Allocation & Emissions)'!T7 -> 0 | O2: ='Supply (Allocation & Emissions)'!U7 -> 0 | P2: ='Supply (Allocation & Emissions)'!V7 -> 0 | Q2: ='Supply (Allocation & Emissions)'!W7 -> 0 | R2: ='Supply (Allocation & Emissions)'!X7 -> 0 | S2: ='Supply (Allocation & Emissions)'!Y7 -> 0 | T2: ='Supply (Allocation & Emissions)'!Z7 -> 0 | U2: ='Supply (Allocation & Emissions)'!AA7 -> 0 | ... W2: ='Supply (Allocation & Emissions)'!AC7 -> 0
A3: ='Supply (Allocation & Emissions)'!H8 -> Cliff Months | B3: ='Supply (Allocation & Emissions)'!I8 -> 12 | C3: ='Supply (Allocation & Emissions)'!J8 -> 12 | D3: ='Supply (Allocation & Emissions)'!K8 -> 6 | E3: =#REF! -> #REF! | F3: ='Supply (Allocation & Emissions)'!L8 -> 12 | G3: ='Supply (Allocation & Emissions)'!M8 -> 6 | H3: ='Supply (Allocation & Emissions)'!N8 -> 0 | I3: ='Supply (Allocation & Emissions)'!P8 -> 0 | J3: ='Supply (Allocation & Emissions)'!Q8 -> 0 | K3: ='Supply (Allocation & Emissions)'!R8 -> 0 | L3: ='Supply (Allocation & Emissions)'!S8 -> 0 | M3: =#REF! -> #REF! | N3: ='Supply (Allocation & Emissions)'!T8 -> 0 | O3: ='Supply (Allocation & Emissions)'!U8 -> 0 | P3: ='Supply (Allocation & Emissions)'!V8 -> 0 | Q3: ='Supply (Allocation & Emissions)'!W8 -> 0 | R3: ='Supply (Allocation & Emissions)'!X8 -> 0 | S3: ='Supply (Allocation & Emissions)'!Y8 -> 0 | T3: ='Supply (Allocation & Emissions)'!Z8 -> 0 | U3: ='Supply (Allocation & Emissions)'!AA8 -> 0 | ... W3: ='Supply (Allocation & Emissions)'!AC8 -> 0
A4: ='Supply (Allocation & Emissions)'!H9 -> Delay Months | B4: ='Supply (Allocation & Emissions)'!I9 -> 0 | C4: ='Supply (Allocation & Emissions)'!J9 -> 0 | D4: ='Supply (Allocation & Emissions)'!K9 -> 0 | E4: =#REF! -> #REF! | F4: ='Supply (Allocation & Emissions)'!L9 -> 0 | G4: ='Supply (Allocation & Emissions)'!M9 -> 0 | H4: ='Supply (Allocation & Emissions)'!N9 -> 0 | J4: ='Supply (Allocation & Emissions)'!Q9 -> 0 | K4: ='Supply (Allocation & Emissions)'!R9 -> 0 | L4: ='Supply (Allocation & Emissions)'!S9 -> 0 | M4: =#REF! -> #REF! | N4: ='Supply (Allocation & Emissions)'!T9 -> 0 | O4: ='Supply (Allocation & Emissions)'!U9 -> 0 | P4: ='Supply (Allocation & Emissions)'!V9 -> 0 | Q4: ='Supply (Allocation & Emissions)'!W9 -> 0 | R4: ='Supply (Allocation & Emissions)'!X9 -> 0 | S4: ='Supply (Allocation & Emissions)'!Y9 -> 0 | T4: ='Supply (Allocation & Emissions)'!Z9 -> 0 | U4: ='Supply (Allocation & Emissions)'!AA9 -> 0 | ... W4: ='Supply (Allocation & Emissions)'!AC9 -> 0
A5: ='Supply (Allocation & Emissions)'!H10 -> Spacing Months | B5: ='Supply (Allocation & Emissions)'!I10 -> 0 | C5: ='Supply (Allocation & Emissions)'!J10 -> 0 | D5: ='Supply (Allocation & Emissions)'!K10 -> 0 | E5: =#REF! -> #REF! | F5: ='Supply (Allocation & Emissions)'!L10 -> 0 | G5: ='Supply (Allocation & Emissions)'!M10 -> 0 | H5: ='Supply (Allocation & Emissions)'!N10 -> 0 | I5: ='Supply (Allocation & Emissions)'!P10 -> 0 | J5: ='Supply (Allocation & Emissions)'!Q10 -> 0 | K5: ='Supply (Allocation & Emissions)'!R10 -> 0 | L5: ='Supply (Allocation & Emissions)'!S10 -> 0 | M5: =#REF! -> #REF! | N5: ='Supply (Allocation & Emissions)'!T10 -> 0 | O5: ='Supply (Allocation & Emissions)'!U10 -> 0 | P5: ='Supply (Allocation & Emissions)'!V10 -> 0 | Q5: ='Supply (Allocation & Emissions)'!W10 -> 0 | R5: ='Supply (Allocation & Emissions)'!X10 -> 0 | S5: ='Supply (Allocation & Emissions)'!Y10 -> 0 | T5: ='Supply (Allocation & Emissions)'!Z10 -> 0 | U5: ='Supply (Allocation & Emissions)'!AA10 -> 0 | ... W5: ='Supply (Allocation & Emissions)'!AC10 -> 0
A8: Unnormalized Value at Start | B8: =IF(B2=0,0,OFFSET(B12,B4+1,0)) -> 0 | C8: =IF(C2=0,0,OFFSET(C12,C4+1,0)) -> 0 | D8: =IF(D2=0,0,OFFSET(D12,D4+1,0)) -> 0 | E8: =IF(E2=0,0,OFFSET(E12,E4+1,0)) -> #REF! | F8: =IF(F2=0,0,OFFSET(F12,F4+1,0)) -> 0 | G8: =IF(G2=0,0,OFFSET(G12,G4+1,0)) -> 0 | H8: =IF(H2=0,0,OFFSET(H12,H4+1,0)) -> 0 | I8: =IF(I2=0,0,OFFSET(I12,I4+1,0)) -> 0 | ... W8: =IF(W2=0,0,OFFSET(W12,W4+1,0)) -> 0
A9: Unnormalized Value at End | B9: =IF(B2=0,1,OFFSET(B12,B2+B4+1,0)) -> 1 | C9: =IF(C2=0,1,OFFSET(C12,C2+C4+1,0)) -> 1 | D9: =IF(D2=0,1,OFFSET(D12,D2+D4+1,0)) -> 1 | E9: =IF(E2=0,1,OFFSET(E12,E2+E4+1,0)) -> #REF! | F9: =IF(F2=0,1,OFFSET(F12,F2+F4+1,0)) -> 1 | G9: =IF(G2=0,1,OFFSET(G12,G2+G4+1,0)) -> 1 | H9: =IF(H2=0,1,OFFSET(H12,H2+H4+1,0)) -> 1 | I9: =IF(I2=0,1,OFFSET(I12,I2+I4+1,0)) -> 1 | ... W9: =IF(W2=0,1,OFFSET(W12,W2+W4+1,0)) -> 1
A10: Range | B10: =B9-B8 -> 1 | C10: =C9-C8 -> 1 | D10: =D9-D8 -> 1 | E10: =E9-E8 -> #REF! | F10: =F9-F8 -> 1 | G10: =G9-G8 -> 1 | H10: =H9-H8 -> 1 | I10: =I9-I8 -> 1 | ... W10: =W9-W8 -> 1
A12: At End of Month... | B12: Cumulative Percent of Tokens in Circulation/Vested...
A13: 0 | B13: =MIN(1,IF($A13<B$4+B$3,0,IF(B$2=0,1,IF(B$5=0,($A13-B$4)/B$2,IF(MOD($A13-B$4,B$5)=0,($A13-B$4)/B$2,QUOTIENT($A13-B$4,B$5)*B$5/B$2))))) -> 0 | C13: =MIN(1,IF($A13<C$4+C$3,0,IF(C$2=0,1,IF(C$5=0,($A13-C$4)/C$2,IF(MOD($A13-C$4,C$5)=0,($A13-C$4)/C$2,QUOTIENT($A13-C$4,C$5)*C$5/C$2))))) -> 0 | D13: =MIN(1,IF($A13<D$4+D$3,0,IF(D$2=0,1,IF(D$5=0,($A13-D$4)/D$2,IF(MOD($A13-D$4,D$5)=0,($A13-D$4)/D$2,QUOTIENT($A13-D$4,D$5)*D$5/D$2))))) -> 0 | E13: =MIN(1,IF($A13<E$4+E$3,0,IF(E$2=0,1,IF(E$5=0,($A13-E$4)/E$2,IF(MOD($A13-E$4,E$5)=0,($A13-E$4)/E$2,QUOTIENT($A13-E$4,E$5)*E$5/E$2))))) -> #REF! | F13: =MIN(1,IF($A13<F$4+F$3,0,IF(F$2=0,1,IF(F$5=0,($A13-F$4)/F$2,IF(MOD($A13-F$4,F$5)=0,($A13-F$4)/F$2,QUOTIENT($A13-F$4,F$5)*F$5/F$2))))) -> 0 | G13: =MIN(1,IF($A13<G$4+G$3,0,IF(G$2=0,1,IF(G$5=0,($A13-G$4)/G$2,IF(MOD($A13-G$4,G$5)=0,($A13-G$4)/G$2,QUOTIENT($A13-G$4,G$5)*G$5/G$2))))) -> 0 | H13: =MIN(1,IF($A13<H$4+H$3,0,IF(H$2=0,1,IF(H$5=0,($A13-H$4)/H$2,IF(MOD($A13-H$4,H$5)=0,($A13-H$4)/H$2,QUOTIENT($A13-H$4,H$5)*H$5/H$2))))) -> 0 | I13: =MIN(1,IF($A13<I$4+I$3,0,IF(I$2=0,1,IF(I$5=0,($A13-I$4)/I$2,IF(MOD($A13-I$4,I$5)=0,($A13-I$4)/I$2,QUOTIENT($A13-I$4,I$5)*I$5/I$2))))) -> 0 | ... W13: =MIN(1,IF($A13<W$4+W$3,0,IF(W$2=0,1,IF(W$5=0,($A13-W$4)/W$2,IF(MOD($A13-W$4,W$5)=0,($A13-W$4)/W$2,QUOTIENT($A13-W$4,W$5)*W$5/W$2))))) -> 1
A14: 1 | B14: =MIN(1,IF($A14<B$4+B$3,0,IF(B$2=0,1,IF(B$5=0,($A14-B$4)/B$2,IF(MOD($A14-B$4,B$5)=0,($A14-B$4)/B$2,QUOTIENT($A14-B$4,B$5)*B$5/B$2))))) -> 0 | C14: =MIN(1,IF($A14<C$4+C$3,0,IF(C$2=0,1,IF(C$5=0,($A14-C$4)/C$2,IF(MOD($A14-C$4,C$5)=0,($A14-C$4)/C$2,QUOTIENT($A14-C$4,C$5)*C$5/C$2))))) -> 0 | D14: =MIN(1,IF($A14<D$4+D$3,0,IF(D$2=0,1,IF(D$5=0,($A14-D$4)/D$2,IF(MOD($A14-D$4,D$5)=0,($A14-D$4)/D$2,QUOTIENT($A14-D$4,D$5)*D$5/D$2))))) -> 0 | E14: =MIN(1,IF($A14<E$4+E$3,0,IF(E$2=0,1,IF(E$5=0,($A14-E$4)/E$2,IF(MOD($A14-E$4,E$5)=0,($A14-E$4)/E$2,QUOTIENT($A14-E$4,E$5)*E$5/E$2))))) -> #REF! | F14: =MIN(1,IF($A14<F$4+F$3,0,IF(F$2=0,1,IF(F$5=0,($A14-F$4)/F$2,IF(MOD($A14-F$4,F$5)=0,($A14-F$4)/F$2,QUOTIENT($A14-F$4,F$5)*F$5/F$2))))) -> 0 | G14: =MIN(1,IF($A14<G$4+G$3,0,IF(G$2=0,1,IF(G$5=0,($A14-G$4)/G$2,IF(MOD($A14-G$4,G$5)=0,($A14-G$4)/G$2,QUOTIENT($A14-G$4,G$5)*G$5/G$2))))) -> 0 | H14: =MIN(1,IF($A14<H$4+H$3,0,IF(H$2=0,1,IF(H$5=0,($A14-H$4)/H$2,IF(MOD($A14-H$4,H$5)=0,($A14-H$4)/H$2,QUOTIENT($A14-H$4,H$5)*H$5/H$2))))) -> 0.5 | I14: =MIN(1,IF($A14<I$4+I$3,0,IF(I$2=0,1,IF(I$5=0,($A14-I$4)/I$2,IF(MOD($A14-I$4,I$5)=0,($A14-I$4)/I$2,QUOTIENT($A14-I$4,I$5)*I$5/I$2))))) -> 0.16666667 | ... W14: =MIN(1,IF($A14<W$4+W$3,0,IF(W$2=0,1,IF(W$5=0,($A14-W$4)/W$2,IF(MOD($A14-W$4,W$5)=0,($A14-W$4)/W$2,QUOTIENT($A14-W$4,W$5)*W$5/W$2))))) -> 1
A15: 2 | B15: =MIN(1,IF($A15<B$4+B$3,0,IF(B$2=0,1,IF(B$5=0,($A15-B$4)/B$2,IF(MOD($A15-B$4,B$5)=0,($A15-B$4)/B$2,QUOTIENT($A15-B$4,B$5)*B$5/B$2))))) -> 0 | C15: =MIN(1,IF($A15<C$4+C$3,0,IF(C$2=0,1,IF(C$5=0,($A15-C$4)/C$2,IF(MOD($A15-C$4,C$5)=0,($A15-C$4)/C$2,QUOTIENT($A15-C$4,C$5)*C$5/C$2))))) -> 0 | D15: =MIN(1,IF($A15<D$4+D$3,0,IF(D$2=0,1,IF(D$5=0,($A15-D$4)/D$2,IF(MOD($A15-D$4,D$5)=0,($A15-D$4)/D$2,QUOTIENT($A15-D$4,D$5)*D$5/D$2))))) -> 0 | E15: =MIN(1,IF($A15<E$4+E$3,0,IF(E$2=0,1,IF(E$5=0,($A15-E$4)/E$2,IF(MOD($A15-E$4,E$5)=0,($A15-E$4)/E$2,QUOTIENT($A15-E$4,E$5)*E$5/E$2))))) -> #REF! | F15: =MIN(1,IF($A15<F$4+F$3,0,IF(F$2=0,1,IF(F$5=0,($A15-F$4)/F$2,IF(MOD($A15-F$4,F$5)=0,($A15-F$4)/F$2,QUOTIENT($A15-F$4,F$5)*F$5/F$2))))) -> 0 | G15: =MIN(1,IF($A15<G$4+G$3,0,IF(G$2=0,1,IF(G$5=0,($A15-G$4)/G$2,IF(MOD($A15-G$4,G$5)=0,($A15-G$4)/G$2,QUOTIENT($A15-G$4,G$5)*G$5/G$2))))) -> 0 | H15: =MIN(1,IF($A15<H$4+H$3,0,IF(H$2=0,1,IF(H$5=0,($A15-H$4)/H$2,IF(MOD($A15-H$4,H$5)=0,($A15-H$4)/H$2,QUOTIENT($A15-H$4,H$5)*H$5/H$2))))) -> 1 | I15: =MIN(1,IF($A15<I$4+I$3,0,IF(I$2=0,1,IF(I$5=0,($A15-I$4)/I$2,IF(MOD($A15-I$4,I$5)=0,($A15-I$4)/I$2,QUOTIENT($A15-I$4,I$5)*I$5/I$2))))) -> 0.33333333 | ... W15: =MIN(1,IF($A15<W$4+W$3,0,IF(W$2=0,1,IF(W$5=0,($A15-W$4)/W$2,IF(MOD($A15-W$4,W$5)=0,($A15-W$4)/W$2,QUOTIENT($A15-W$4,W$5)*W$5/W$2))))) -> 1
A16: 3 | B16: =MIN(1,IF($A16<B$4+B$3,0,IF(B$2=0,1,IF(B$5=0,($A16-B$4)/B$2,IF(MOD($A16-B$4,B$5)=0,($A16-B$4)/B$2,QUOTIENT($A16-B$4,B$5)*B$5/B$2))))) -> 0 | C16: =MIN(1,IF($A16<C$4+C$3,0,IF(C$2=0,1,IF(C$5=0,($A16-C$4)/C$2,IF(MOD($A16-C$4,C$5)=0,($A16-C$4)/C$2,QUOTIENT($A16-C$4,C$5)*C$5/C$2))))) -> 0 | D16: =MIN(1,IF($A16<D$4+D$3,0,IF(D$2=0,1,IF(D$5=0,($A16-D$4)/D$2,IF(MOD($A16-D$4,D$5)=0,($A16-D$4)/D$2,QUOTIENT($A16-D$4,D$5)*D$5/D$2))))) -> 0 | E16: =MIN(1,IF($A16<E$4+E$3,0,IF(E$2=0,1,IF(E$5=0,($A16-E$4)/E$2,IF(MOD($A16-E$4,E$5)=0,($A16-E$4)/E$2,QUOTIENT($A16-E$4,E$5)*E$5/E$2))))) -> #REF! | F16: =MIN(1,IF($A16<F$4+F$3,0,IF(F$2=0,1,IF(F$5=0,($A16-F$4)/F$2,IF(MOD($A16-F$4,F$5)=0,($A16-F$4)/F$2,QUOTIENT($A16-F$4,F$5)*F$5/F$2))))) -> 0 | G16: =MIN(1,IF($A16<G$4+G$3,0,IF(G$2=0,1,IF(G$5=0,($A16-G$4)/G$2,IF(MOD($A16-G$4,G$5)=0,($A16-G$4)/G$2,QUOTIENT($A16-G$4,G$5)*G$5/G$2))))) -> 0 | H16: =MIN(1,IF($A16<H$4+H$3,0,IF(H$2=0,1,IF(H$5=0,($A16-H$4)/H$2,IF(MOD($A16-H$4,H$5)=0,($A16-H$4)/H$2,QUOTIENT($A16-H$4,H$5)*H$5/H$2))))) -> 1 | I16: =MIN(1,IF($A16<I$4+I$3,0,IF(I$2=0,1,IF(I$5=0,($A16-I$4)/I$2,IF(MOD($A16-I$4,I$5)=0,($A16-I$4)/I$2,QUOTIENT($A16-I$4,I$5)*I$5/I$2))))) -> 0.5 | ... W16: =MIN(1,IF($A16<W$4+W$3,0,IF(W$2=0,1,IF(W$5=0,($A16-W$4)/W$2,IF(MOD($A16-W$4,W$5)=0,($A16-W$4)/W$2,QUOTIENT($A16-W$4,W$5)*W$5/W$2))))) -> 1
A17: 4 | B17: =MIN(1,IF($A17<B$4+B$3,0,IF(B$2=0,1,IF(B$5=0,($A17-B$4)/B$2,IF(MOD($A17-B$4,B$5)=0,($A17-B$4)/B$2,QUOTIENT($A17-B$4,B$5)*B$5/B$2))))) -> 0 | C17: =MIN(1,IF($A17<C$4+C$3,0,IF(C$2=0,1,IF(C$5=0,($A17-C$4)/C$2,IF(MOD($A17-C$4,C$5)=0,($A17-C$4)/C$2,QUOTIENT($A17-C$4,C$5)*C$5/C$2))))) -> 0 | D17: =MIN(1,IF($A17<D$4+D$3,0,IF(D$2=0,1,IF(D$5=0,($A17-D$4)/D$2,IF(MOD($A17-D$4,D$5)=0,($A17-D$4)/D$2,QUOTIENT($A17-D$4,D$5)*D$5/D$2))))) -> 0 | E17: =MIN(1,IF($A17<E$4+E$3,0,IF(E$2=0,1,IF(E$5=0,($A17-E$4)/E$2,IF(MOD($A17-E$4,E$5)=0,($A17-E$4)/E$2,QUOTIENT($A17-E$4,E$5)*E$5/E$2))))) -> #REF! | F17: =MIN(1,IF($A17<F$4+F$3,0,IF(F$2=0,1,IF(F$5=0,($A17-F$4)/F$2,IF(MOD($A17-F$4,F$5)=0,($A17-F$4)/F$2,QUOTIENT($A17-F$4,F$5)*F$5/F$2))))) -> 0 | G17: =MIN(1,IF($A17<G$4+G$3,0,IF(G$2=0,1,IF(G$5=0,($A17-G$4)/G$2,IF(MOD($A17-G$4,G$5)=0,($A17-G$4)/G$2,QUOTIENT($A17-G$4,G$5)*G$5/G$2))))) -> 0 | H17: =MIN(1,IF($A17<H$4+H$3,0,IF(H$2=0,1,IF(H$5=0,($A17-H$4)/H$2,IF(MOD($A17-H$4,H$5)=0,($A17-H$4)/H$2,QUOTIENT($A17-H$4,H$5)*H$5/H$2))))) -> 1 | I17: =MIN(1,IF($A17<I$4+I$3,0,IF(I$2=0,1,IF(I$5=0,($A17-I$4)/I$2,IF(MOD($A17-I$4,I$5)=0,($A17-I$4)/I$2,QUOTIENT($A17-I$4,I$5)*I$5/I$2))))) -> 0.66666667 | ... W17: =MIN(1,IF($A17<W$4+W$3,0,IF(W$2=0,1,IF(W$5=0,($A17-W$4)/W$2,IF(MOD($A17-W$4,W$5)=0,($A17-W$4)/W$2,QUOTIENT($A17-W$4,W$5)*W$5/W$2))))) -> 1
A18: 5 | B18: =MIN(1,IF($A18<B$4+B$3,0,IF(B$2=0,1,IF(B$5=0,($A18-B$4)/B$2,IF(MOD($A18-B$4,B$5)=0,($A18-B$4)/B$2,QUOTIENT($A18-B$4,B$5)*B$5/B$2))))) -> 0 | C18: =MIN(1,IF($A18<C$4+C$3,0,IF(C$2=0,1,IF(C$5=0,($A18-C$4)/C$2,IF(MOD($A18-C$4,C$5)=0,($A18-C$4)/C$2,QUOTIENT($A18-C$4,C$5)*C$5/C$2))))) -> 0 | D18: =MIN(1,IF($A18<D$4+D$3,0,IF(D$2=0,1,IF(D$5=0,($A18-D$4)/D$2,IF(MOD($A18-D$4,D$5)=0,($A18-D$4)/D$2,QUOTIENT($A18-D$4,D$5)*D$5/D$2))))) -> 0 | E18: =MIN(1,IF($A18<E$4+E$3,0,IF(E$2=0,1,IF(E$5=0,($A18-E$4)/E$2,IF(MOD($A18-E$4,E$5)=0,($A18-E$4)/E$2,QUOTIENT($A18-E$4,E$5)*E$5/E$2))))) -> #REF! | F18: =MIN(1,IF($A18<F$4+F$3,0,IF(F$2=0,1,IF(F$5=0,($A18-F$4)/F$2,IF(MOD($A18-F$4,F$5)=0,($A18-F$4)/F$2,QUOTIENT($A18-F$4,F$5)*F$5/F$2))))) -> 0 | G18: =MIN(1,IF($A18<G$4+G$3,0,IF(G$2=0,1,IF(G$5=0,($A18-G$4)/G$2,IF(MOD($A18-G$4,G$5)=0,($A18-G$4)/G$2,QUOTIENT($A18-G$4,G$5)*G$5/G$2))))) -> 0 | H18: =MIN(1,IF($A18<H$4+H$3,0,IF(H$2=0,1,IF(H$5=0,($A18-H$4)/H$2,IF(MOD($A18-H$4,H$5)=0,($A18-H$4)/H$2,QUOTIENT($A18-H$4,H$5)*H$5/H$2))))) -> 1 | I18: =MIN(1,IF($A18<I$4+I$3,0,IF(I$2=0,1,IF(I$5=0,($A18-I$4)/I$2,IF(MOD($A18-I$4,I$5)=0,($A18-I$4)/I$2,QUOTIENT($A18-I$4,I$5)*I$5/I$2))))) -> 0.83333333 | ... W18: =MIN(1,IF($A18<W$4+W$3,0,IF(W$2=0,1,IF(W$5=0,($A18-W$4)/W$2,IF(MOD($A18-W$4,W$5)=0,($A18-W$4)/W$2,QUOTIENT($A18-W$4,W$5)*W$5/W$2))))) -> 1
A19: 6 | B19: =MIN(1,IF($A19<B$4+B$3,0,IF(B$2=0,1,IF(B$5=0,($A19-B$4)/B$2,IF(MOD($A19-B$4,B$5)=0,($A19-B$4)/B$2,QUOTIENT($A19-B$4,B$5)*B$5/B$2))))) -> 0 | C19: =MIN(1,IF($A19<C$4+C$3,0,IF(C$2=0,1,IF(C$5=0,($A19-C$4)/C$2,IF(MOD($A19-C$4,C$5)=0,($A19-C$4)/C$2,QUOTIENT($A19-C$4,C$5)*C$5/C$2))))) -> 0 | D19: =MIN(1,IF($A19<D$4+D$3,0,IF(D$2=0,1,IF(D$5=0,($A19-D$4)/D$2,IF(MOD($A19-D$4,D$5)=0,($A19-D$4)/D$2,QUOTIENT($A19-D$4,D$5)*D$5/D$2))))) -> 0.25 | E19: =MIN(1,IF($A19<E$4+E$3,0,IF(E$2=0,1,IF(E$5=0,($A19-E$4)/E$2,IF(MOD($A19-E$4,E$5)=0,($A19-E$4)/E$2,QUOTIENT($A19-E$4,E$5)*E$5/E$2))))) -> #REF! | F19: =MIN(1,IF($A19<F$4+F$3,0,IF(F$2=0,1,IF(F$5=0,($A19-F$4)/F$2,IF(MOD($A19-F$4,F$5)=0,($A19-F$4)/F$2,QUOTIENT($A19-F$4,F$5)*F$5/F$2))))) -> 0 | G19: =MIN(1,IF($A19<G$4+G$3,0,IF(G$2=0,1,IF(G$5=0,($A19-G$4)/G$2,IF(MOD($A19-G$4,G$5)=0,($A19-G$4)/G$2,QUOTIENT($A19-G$4,G$5)*G$5/G$2))))) -> 0.25 | H19: =MIN(1,IF($A19<H$4+H$3,0,IF(H$2=0,1,IF(H$5=0,($A19-H$4)/H$2,IF(MOD($A19-H$4,H$5)=0,($A19-H$4)/H$2,QUOTIENT($A19-H$4,H$5)*H$5/H$2))))) -> 1 | I19: =MIN(1,IF($A19<I$4+I$3,0,IF(I$2=0,1,IF(I$5=0,($A19-I$4)/I$2,IF(MOD($A19-I$4,I$5)=0,($A19-I$4)/I$2,QUOTIENT($A19-I$4,I$5)*I$5/I$2))))) -> 1 | ... W19: =MIN(1,IF($A19<W$4+W$3,0,IF(W$2=0,1,IF(W$5=0,($A19-W$4)/W$2,IF(MOD($A19-W$4,W$5)=0,($A19-W$4)/W$2,QUOTIENT($A19-W$4,W$5)*W$5/W$2))))) -> 1
A20: 7 | B20: =MIN(1,IF($A20<B$4+B$3,0,IF(B$2=0,1,IF(B$5=0,($A20-B$4)/B$2,IF(MOD($A20-B$4,B$5)=0,($A20-B$4)/B$2,QUOTIENT($A20-B$4,B$5)*B$5/B$2))))) -> 0 | C20: =MIN(1,IF($A20<C$4+C$3,0,IF(C$2=0,1,IF(C$5=0,($A20-C$4)/C$2,IF(MOD($A20-C$4,C$5)=0,($A20-C$4)/C$2,QUOTIENT($A20-C$4,C$5)*C$5/C$2))))) -> 0 | D20: =MIN(1,IF($A20<D$4+D$3,0,IF(D$2=0,1,IF(D$5=0,($A20-D$4)/D$2,IF(MOD($A20-D$4,D$5)=0,($A20-D$4)/D$2,QUOTIENT($A20-D$4,D$5)*D$5/D$2))))) -> 0.29166667 | E20: =MIN(1,IF($A20<E$4+E$3,0,IF(E$2=0,1,IF(E$5=0,($A20-E$4)/E$2,IF(MOD($A20-E$4,E$5)=0,($A20-E$4)/E$2,QUOTIENT($A20-E$4,E$5)*E$5/E$2))))) -> #REF! | F20: =MIN(1,IF($A20<F$4+F$3,0,IF(F$2=0,1,IF(F$5=0,($A20-F$4)/F$2,IF(MOD($A20-F$4,F$5)=0,($A20-F$4)/F$2,QUOTIENT($A20-F$4,F$5)*F$5/F$2))))) -> 0 | G20: =MIN(1,IF($A20<G$4+G$3,0,IF(G$2=0,1,IF(G$5=0,($A20-G$4)/G$2,IF(MOD($A20-G$4,G$5)=0,($A20-G$4)/G$2,QUOTIENT($A20-G$4,G$5)*G$5/G$2))))) -> 0.29166667 | H20: =MIN(1,IF($A20<H$4+H$3,0,IF(H$2=0,1,IF(H$5=0,($A20-H$4)/H$2,IF(MOD($A20-H$4,H$5)=0,($A20-H$4)/H$2,QUOTIENT($A20-H$4,H$5)*H$5/H$2))))) -> 1 | I20: =MIN(1,IF($A20<I$4+I$3,0,IF(I$2=0,1,IF(I$5=0,($A20-I$4)/I$2,IF(MOD($A20-I$4,I$5)=0,($A20-I$4)/I$2,QUOTIENT($A20-I$4,I$5)*I$5/I$2))))) -> 1 | ... W20: =MIN(1,IF($A20<W$4+W$3,0,IF(W$2=0,1,IF(W$5=0,($A20-W$4)/W$2,IF(MOD($A20-W$4,W$5)=0,($A20-W$4)/W$2,QUOTIENT($A20-W$4,W$5)*W$5/W$2))))) -> 1
A21: 8 | B21: =MIN(1,IF($A21<B$4+B$3,0,IF(B$2=0,1,IF(B$5=0,($A21-B$4)/B$2,IF(MOD($A21-B$4,B$5)=0,($A21-B$4)/B$2,QUOTIENT($A21-B$4,B$5)*B$5/B$2))))) -> 0 | C21: =MIN(1,IF($A21<C$4+C$3,0,IF(C$2=0,1,IF(C$5=0,($A21-C$4)/C$2,IF(MOD($A21-C$4,C$5)=0,($A21-C$4)/C$2,QUOTIENT($A21-C$4,C$5)*C$5/C$2))))) -> 0 | D21: =MIN(1,IF($A21<D$4+D$3,0,IF(D$2=0,1,IF(D$5=0,($A21-D$4)/D$2,IF(MOD($A21-D$4,D$5)=0,($A21-D$4)/D$2,QUOTIENT($A21-D$4,D$5)*D$5/D$2))))) -> 0.33333333 | E21: =MIN(1,IF($A21<E$4+E$3,0,IF(E$2=0,1,IF(E$5=0,($A21-E$4)/E$2,IF(MOD($A21-E$4,E$5)=0,($A21-E$4)/E$2,QUOTIENT($A21-E$4,E$5)*E$5/E$2))))) -> #REF! | F21: =MIN(1,IF($A21<F$4+F$3,0,IF(F$2=0,1,IF(F$5=0,($A21-F$4)/F$2,IF(MOD($A21-F$4,F$5)=0,($A21-F$4)/F$2,QUOTIENT($A21-F$4,F$5)*F$5/F$2))))) -> 0 | G21: =MIN(1,IF($A21<G$4+G$3,0,IF(G$2=0,1,IF(G$5=0,($A21-G$4)/G$2,IF(MOD($A21-G$4,G$5)=0,($A21-G$4)/G$2,QUOTIENT($A21-G$4,G$5)*G$5/G$2))))) -> 0.33333333 | H21: =MIN(1,IF($A21<H$4+H$3,0,IF(H$2=0,1,IF(H$5=0,($A21-H$4)/H$2,IF(MOD($A21-H$4,H$5)=0,($A21-H$4)/H$2,QUOTIENT($A21-H$4,H$5)*H$5/H$2))))) -> 1 | I21: =MIN(1,IF($A21<I$4+I$3,0,IF(I$2=0,1,IF(I$5=0,($A21-I$4)/I$2,IF(MOD($A21-I$4,I$5)=0,($A21-I$4)/I$2,QUOTIENT($A21-I$4,I$5)*I$5/I$2))))) -> 1 | ... W21: =MIN(1,IF($A21<W$4+W$3,0,IF(W$2=0,1,IF(W$5=0,($A21-W$4)/W$2,IF(MOD($A21-W$4,W$5)=0,($A21-W$4)/W$2,QUOTIENT($A21-W$4,W$5)*W$5/W$2))))) -> 1
A22: 9 | B22: =MIN(1,IF($A22<B$4+B$3,0,IF(B$2=0,1,IF(B$5=0,($A22-B$4)/B$2,IF(MOD($A22-B$4,B$5)=0,($A22-B$4)/B$2,QUOTIENT($A22-B$4,B$5)*B$5/B$2))))) -> 0 | C22: =MIN(1,IF($A22<C$4+C$3,0,IF(C$2=0,1,IF(C$5=0,($A22-C$4)/C$2,IF(MOD($A22-C$4,C$5)=0,($A22-C$4)/C$2,QUOTIENT($A22-C$4,C$5)*C$5/C$2))))) -> 0 | D22: =MIN(1,IF($A22<D$4+D$3,0,IF(D$2=0,1,IF(D$5=0,($A22-D$4)/D$2,IF(MOD($A22-D$4,D$5)=0,($A22-D$4)/D$2,QUOTIENT($A22-D$4,D$5)*D$5/D$2))))) -> 0.375 | E22: =MIN(1,IF($A22<E$4+E$3,0,IF(E$2=0,1,IF(E$5=0,($A22-E$4)/E$2,IF(MOD($A22-E$4,E$5)=0,($A22-E$4)/E$2,QUOTIENT($A22-E$4,E$5)*E$5/E$2))))) -> #REF! | F22: =MIN(1,IF($A22<F$4+F$3,0,IF(F$2=0,1,IF(F$5=0,($A22-F$4)/F$2,IF(MOD($A22-F$4,F$5)=0,($A22-F$4)/F$2,QUOTIENT($A22-F$4,F$5)*F$5/F$2))))) -> 0 | G22: =MIN(1,IF($A22<G$4+G$3,0,IF(G$2=0,1,IF(G$5=0,($A22-G$4)/G$2,IF(MOD($A22-G$4,G$5)=0,($A22-G$4)/G$2,QUOTIENT($A22-G$4,G$5)*G$5/G$2))))) -> 0.375 | H22: =MIN(1,IF($A22<H$4+H$3,0,IF(H$2=0,1,IF(H$5=0,($A22-H$4)/H$2,IF(MOD($A22-H$4,H$5)=0,($A22-H$4)/H$2,QUOTIENT($A22-H$4,H$5)*H$5/H$2))))) -> 1 | I22: =MIN(1,IF($A22<I$4+I$3,0,IF(I$2=0,1,IF(I$5=0,($A22-I$4)/I$2,IF(MOD($A22-I$4,I$5)=0,($A22-I$4)/I$2,QUOTIENT($A22-I$4,I$5)*I$5/I$2))))) -> 1 | ... W22: =MIN(1,IF($A22<W$4+W$3,0,IF(W$2=0,1,IF(W$5=0,($A22-W$4)/W$2,IF(MOD($A22-W$4,W$5)=0,($A22-W$4)/W$2,QUOTIENT($A22-W$4,W$5)*W$5/W$2))))) -> 1
